Workbook

Sheet Sheet2
A1: TICK | B1: (All)
A2: CURR | B2: (All)
A4: Sum of VALUE
A5: Row Labels | B5: 2016 | C5: 2017 | D5: 2018 | E5: 2019 | F5: 2020 | G5: 2021 | H5: 2022 | I5: 2023 | J5: 2024 | K5: Grand Total
A6: Revenue | B6: 4958000000 | C6: 5509000000 | D6: 7370000000 | E6: 6547000000 | F6: 4442000000 | G6: 8154000000 | H6: 12158000000 | I6: 8289000000 | J6: 9749000000 | K6: 67176000000
A7: Investment income | B7: 8000000 | C7: 19000000 | D7: 22000000 | E7: 13000000 | F7: 7000000 | G7: 8000000 | H7: 10000000 | I7: 10000000 | J7: 12000000 | K7: 109000000
A8: Other Revenue | B8: -417000000 | C8: -397000000 | D8: 0 | E8: 43000000 | F8: 0 | G8: 161000000 | H8: 1073000000 | I8: 0 | J8: 0 | K8: 463000000
A9: Revenue | B9: 5367000000 | C9: 5887000000 | D9: 7348000000 | E9: 6491000000 | F9: 4435000000 | G9: 7985000000 | H9: 11075000000 | I9: 8279000000 | J9: 9737000000 | K9: 66604000000
A10: Cost of Revenue | B10: 8624000000 | C10: 7718000000 | D10: 8384000000 | E10: 9150000000 | F10: 7060000000 | G10: 8890000000 | H10: 9640000000 | I10: 8104000000 | J10: 10870000000 | K10: 78440000000
A11: Gross Profit | B11: 1055000000 | C11: 2028000000 | D11: 3156000000 | E11: 1916000000 | F11: 905000000 | G11: 3540000000 | H11: 6255000000 | I11: 4227000000 | J11: 4302000000 | K11: 27384000000
A12: Operating Expenses | B12: 1199000000 | C12: 1181000000 | D12: 1187000000 | E12: 1471000000 | F12: 732000000 | G12: 848000000 | H12: 1173000000 | I12: 869000000 | J12: 1103000000 | K12: 9763000000
A13: Operating Income | B13: -144000000 | C13: 847000000 | D13: 1969000000 | E13: 445000000 | F13: 173000000 | G13: 2692000000 | H13: 5082000000 | I13: 3358000000 | J13: 3199000000 | K13: 17621000000
A14: Operating Income | B14: -144000000 | C14: 847000000 | D14: 1969000000 | E14: 445000000 | F14: 173000000 | G14: 2692000000 | H14: 5082000000 | I14: 3358000000 | J14: 3199000000 | K14: 17621000000
A15: Interest & Other | B15: 1000000 | C15: 1000000 | D15: 94000000 | E15: 13000000 | F15: 7000000 | G15: -96000000 | H15: 10000000 | I15: 10000000 | J15: 12000000 | K15: 52000000
A16: Interest Expense | B16: 417000000 | C16: 397000000 | D16: 478000000 | E16: 400000000 | F16: 434000000 | G16: 418000000 | H16: 322000000 | I16: 331000000 | J16: 379000000 | K16: 3576000000
A17: Net Int. Income | B17: -416000000 | C17: -396000000 | D17: -384000000 | E17: -387000000 | F17: -427000000 | G17: -514000000 | H17: -312000000 | I17: -321000000 | J17: -367000000 | K17: -3524000000
... A23: Grand Total | B23: 10924000000 | C23: 20424000000 | D23: 24116000000 | E23: 11345000000 | F23: -1145000000 | G23: 29034000000 | H23: 49460000000 | I23: 33478000000 | J23: 33109000000 | K23: 210745000000
A27: GP% | B27: =B11/B9 -> 0.19657164 | C27: =C11/C9 -> 0.34448785 | D27: =D11/D9 -> 0.42950463 | E27: =E11/E9 -> 0.29517794 | F27: =F11/F9 -> 0.20405862 | G27: =G11/G9 -> 0.44333125 | H27: =H11/H9 -> 0.56478555 | I27: =I11/I9 -> 0.51056891 | J27: =J11/J9 -> 0.44181986 | K27: =K11/K6 -> 0.40764559 | L27: =L11/L6 -> #DIV/0! | M27: =M11/M6 -> #DIV/0! | N27: =N11/N6 -> #DIV/0! | O27: =O11/O6 -> #DIV/0! | P27: =P11/P6 -> #DIV/0! | Q27: =Q11/Q6 -> #DIV/0! | R27: =R11/R6 -> #DIV/0! | ... V27: =V11/V6 -> #DIV/0!
A28: Net Income % | B28: =B21/B9 -> -0.49282653 | C28: =C21/C9 -> 0.47681332 | D28: =D21/D9 -> 0.044365814 | E28: =E21/E9 -> -0.90325065 | F28: =F21/F9 -> -2.1844419 | G28: =G21/G9 -> 0.31772073 | H28: =H21/H9 -> 0.70031603 | I28: =I21/I9 -> 0.73221404 | J28: =J21/J9 -> 0.19739139 | K28: =K21/K6 -> 0.047844468 | L28: =L21/L6 -> #DIV/0! | M28: =M21/M6 -> #DIV/0! | N28: =N21/N6 -> #DIV/0! | O28: =O21/O6 -> #DIV/0! | P28: =P21/P6 -> #DIV/0! | Q28: =Q21/Q6 -> #DIV/0! | R28: =R21/R6 -> #DIV/0! | ... V28: =V21/V6 -> #DIV/0!
A29: # Shares Millions | B29: 379 | C29: 381 | D29: 375 | E29: 376 | F29: 377 | G29: 347 | H29: 312 | I29: 304 | J29: 365 | K29: =SUM(B29:J29) -> 3216
A30: EPS | B30: =B21/(B29*1000000) -> -6.9788918 | C30: =C21/(C29*1000000) -> 7.3674541 | D30: =D21/(D29*1000000) -> 0.86933333 | E30: =E21/(E29*1000000) -> -15.593085 | F30: =F21/(F29*1000000) -> -25.697613 | G30: =G21/(G29*1000000) -> 7.3112392 | H30: =H21/(H29*1000000) -> 24.858974 | I30: =I21/(I29*1000000) -> 19.940789 | ... K30: =K21/(K29*1000000) -> 0.99937811
A31: SPS | B31: =B9/(B29*1000000) -> 14.16095 | C31: =C9/(C29*1000000) -> 15.451444 | D31: =D9/(D29*1000000) -> 19.594667 | E31: =E9/(E29*1000000) -> 17.263298 | F31: =F9/(F29*1000000) -> 11.763926 | G31: =G9/(G29*1000000) -> 23.011527 | H31: =H9/(H29*1000000) -> 35.496795 | I31: =I9/(I29*1000000) -> 27.233553 | ... K31: =K9/(K29*1000000) -> 20.710199

Sheet MAP
A1: Section | B1: Row Label | C1: Section | D1: Description / Notes | E1: Short Name
A2: Revenue | B2: totalRevenue | C2: Revenue | D2: Total sales and operating revenue | E2: Revenue
A3: Revenue | B3: investmentIncomeNet | C3: Revenue | D3: Net investment income | E3: Investment income
A4: Revenue | B4: interestIncome | C4: Revenue | D4: Interest earned | E4: Investment income
A5: Revenue | B5: nonInterestIncome | C5: Revenue | D5: Other non-interest income | E5: Other Revenue
A6: Revenue | B6: otherNonOperatingIncome | C6: Revenue | D6: Other income not from core operations | E6: Other Revenue
A7: Cost of Revenue | B7: costOfRevenue | C7: Cost of Revenue | D7: Direct costs of revenue | E7: COGS
A8: Cost of Revenue | B8: costofGoodsAndServicesSold | C8: Cost of Revenue | D8: Direct costs of goods/services sold | E8: COGS
A9: Gross Profit | B9: grossProfit | C9: Gross Profit | D9: Revenue minus cost of revenue | E9: Gross Profit
A10: Operating Expenses | B10: sellingGeneralAndAdministrative | C10: Operating Expenses | D10: SG&A expenses | E10: SG&A
A11: Operating Expenses | B11: researchAndDevelopment | C11: Operating Expenses | D11: R&D expenses | E11: R&D
A12: Operating Expenses | B12: operatingExpenses | C12: Operating Expenses | D12: Other operating expenses | E12: OPEX
... A25: Comprehensive Income | B25: comprehensiveIncomeNetOfTax | C25: Comprehensive Income | D25: Net comprehensive income after tax | E25: Comp. Income

Sheet Sheet1
A1: TICK | B1: DATE | C1: CURR | D1: DATUM | E1: VALUE | F1: RECORD_DATE | G1: DATUM_LVL1 | H1: DATUM_LVL2
A2: APA | B2: 45657 | C2: USD | D2: grossProfit | E2: 4302000000 | F2: 45986.119 | G2: =VLOOKUP(D2,MAP!B:C,2,0) -> Gross Profit | H2: =VLOOKUP(D2,MAP!B:G,4,0) -> Gross Profit
A3: APA | B3: 45291 | C3: USD | D3: grossProfit | E3: 4227000000 | F3: 45986.119 | G3: =VLOOKUP(D3,MAP!B:C,2,0) -> Gross Profit | H3: =VLOOKUP(D3,MAP!B:G,4,0) -> Gross Profit
A4: APA | B4: 44926 | C4: USD | D4: grossProfit | E4: 6255000000 | F4: 45986.119 | G4: =VLOOKUP(D4,MAP!B:C,2,0) -> Gross Profit | H4: =VLOOKUP(D4,MAP!B:G,4,0) -> Gross Profit
A5: APA | B5: 44561 | C5: USD | D5: grossProfit | E5: 3540000000 | F5: 45986.119 | G5: =VLOOKUP(D5,MAP!B:C,2,0) -> Gross Profit | H5: =VLOOKUP(D5,MAP!B:G,4,0) -> Gross Profit
A6: APA | B6: 44196 | C6: USD | D6: grossProfit | E6: 905000000 | F6: 45986.119 | G6: =VLOOKUP(D6,MAP!B:C,2,0) -> Gross Profit | H6: =VLOOKUP(D6,MAP!B:G,4,0) -> Gross Profit
A7: APA | B7: 43830 | C7: USD | D7: grossProfit | E7: 1916000000 | F7: 45986.119 | G7: =VLOOKUP(D7,MAP!B:C,2,0) -> Gross Profit | H7: =VLOOKUP(D7,MAP!B:G,4,0) -> Gross Profit
A8: APA | B8: 43465 | C8: USD | D8: grossProfit | E8: 3156000000 | F8: 45986.119 | G8: =VLOOKUP(D8,MAP!B:C,2,0) -> Gross Profit | H8: =VLOOKUP(D8,MAP!B:G,4,0) -> Gross Profit
A9: APA | B9: 43100 | C9: USD | D9: grossProfit | E9: 2028000000 | F9: 45986.119 | G9: =VLOOKUP(D9,MAP!B:C,2,0) -> Gross Profit | H9: =VLOOKUP(D9,MAP!B:G,4,0) -> Gross Profit
A10: APA | B10: 42735 | C10: USD | D10: grossProfit | E10: 1055000000 | F10: 45986.119 | G10: =VLOOKUP(D10,MAP!B:C,2,0) -> Gross Profit | H10: =VLOOKUP(D10,MAP!B:G,4,0) -> Gross Profit
A11: APA | B11: 42369 | C11: USD | D11: grossProfit | E11: -25054000000 | F11: 45986.119 | G11: =VLOOKUP(D11,MAP!B:C,2,0) -> Gross Profit | H11: =VLOOKUP(D11,MAP!B:G,4,0) -> Gross Profit
A12: APA | B12: 42004 | C12: USD | D12: grossProfit | E12: 839000000 | F12: 45986.119 | G12: =VLOOKUP(D12,MAP!B:C,2,0) -> Gross Profit | H12: =VLOOKUP(D12,MAP!B:G,4,0) -> Gross Profit
A13: APA | B13: 41639 | C13: USD | D13: grossProfit | E13: 6349000000 | F13: 45986.119 | G13: =VLOOKUP(D13,MAP!B:C,2,0) -> Gross Profit | H13: =VLOOKUP(D13,MAP!B:G,4,0) -> Gross Profit
... A121: APA | B121: 38717 | C121: USD | D121: sellingGeneralAndAdministrative | E121: 198272000 | F121: 45986.119 | G121: =VLOOKUP(D121,MAP!B:C,2,0) -> Operating Expenses | H121: =VLOOKUP(D121,MAP!B:G,4,0) -> SG&A
A122: APA | B122: 45657 | C122: USD | D122: researchAndDevelopment | F122: 45986.119 | G122: =VLOOKUP(D122,MAP!B:C,2,0) -> Operating Expenses | H122: =VLOOKUP(D122,MAP!B:G,4,0) -> R&D
A123: APA | B123: 45291 | C123: USD | D123: researchAndDevelopment | F123: 45986.119 | G123: =VLOOKUP(D123,MAP!B:C,2,0) -> Operating Expenses | H123: =VLOOKUP(D123,MAP!B:G,4,0) -> R&D
A124: APA | B124: 44926 | C124: USD | D124: researchAndDevelopment | F124: 45986.119 | G124: =VLOOKUP(D124,MAP!B:C,2,0) -> Operating Expenses | H124: =VLOOKUP(D124,MAP!B:G,4,0) -> R&D
A125: APA | B125: 44561 | C125: USD | D125: researchAndDevelopment | F125: 45986.119 | G125: =VLOOKUP(D125,MAP!B:C,2,0) -> Operating Expenses | H125: =VLOOKUP(D125,MAP!B:G,4,0) -> R&D
A126: APA | B126: 44196 | C126: USD | D126: researchAndDevelopment | F126: 45986.119 | G126: =VLOOKUP(D126,MAP!B:C,2,0) -> Operating Expenses | H126: =VLOOKUP(D126,MAP!B:G,4,0) -> R&D
A127: APA | B127: 43830 | C127: USD | D127: researchAndDevelopment | F127: 45986.119 | G127: =VLOOKUP(D127,MAP!B:C,2,0) -> Operating Expenses | H127: =VLOOKUP(D127,MAP!B:G,4,0) -> R&D
A128: APA | B128: 43465 | C128: USD | D128: researchAndDevelopment | E128: 0 | F128: 45986.119 | G128: =VLOOKUP(D128,MAP!B:C,2,0) -> Operating Expenses | H128: =VLOOKUP(D128,MAP!B:G,4,0) -> R&D
A129: APA | B129: 43100 | C129: USD | D129: researchAndDevelopment | E129: 0 | F129: 45986.119 | G129: =VLOOKUP(D129,MAP!B:C,2,0) -> Operating Expenses | H129: =VLOOKUP(D129,MAP!B:G,4,0) -> R&D
A130: APA | B130: 42735 | C130: USD | D130: researchAndDevelopment | E130: 0 | F130: 45986.119 | G130: =VLOOKUP(D130,MAP!B:C,2,0) -> Operating Expenses | H130: =VLOOKUP(D130,MAP!B:G,4,0) -> R&D
A131: APA | B131: 42369 | C131: USD | D131: researchAndDevelopment | E131: 0 | F131: 45986.119 | G131: =VLOOKUP(D131,MAP!B:C,2,0) -> Operating Expenses | H131: =VLOOKUP(D131,MAP!B:G,4,0) -> R&D
A132: APA | B132: 42004 | C132: USD | D132: researchAndDevelopment | E132: 0 | F132: 45986.119 | G132: =VLOOKUP(D132,MAP!B:C,2,0) -> Operating Expenses | H132: =VLOOKUP(D132,MAP!B:G,4,0) -> R&D
A133: APA | B133: 41639 | C133: USD | D133: researchAndDevelopment | E133: 0 | F133: 45986.119 | G133: =VLOOKUP(D133,MAP!B:C,2,0) -> Operating Expenses | H133: =VLOOKUP(D133,MAP!B:G,4,0) -> R&D
A134: APA | B134: 41274 | C134: USD | D134: researchAndDevelopment | E134: 0 | F134: 45986.119 | G134: =VLOOKUP(D134,MAP!B:C,2,0) -> Operating Expenses | H134: =VLOOKUP(D134,MAP!B:G,4,0) -> R&D
A135: APA | B135: 40908 | C135: USD | D135: researchAndDevelopment | E135: 0 | F135: 45986.119 | G135: =VLOOKUP(D135,MAP!B:C,2,0) -> Operating Expenses | H135: =VLOOKUP(D135,MAP!B:G,4,0) -> R&D
A136: APA | B136: 40543 | C136: USD | D136: researchAndDevelopment | E136: 0 | F136: 45986.119 | G136: =VLOOKUP(D136,MAP!B:C,2,0) -> Operating Expenses | H136: =VLOOKUP(D136,MAP!B:G,4,0) -> R&D
A137: APA | B137: 40178 | C137: USD | D137: researchAndDevelopment | E137: 0 | F137: 45986.119 | G137: =VLOOKUP(D137,MAP!B:C,2,0) -> Operating Expenses | H137: =VLOOKUP(D137,MAP!B:G,4,0) -> R&D
A138: APA | B138: 39813 | C138: USD | D138: researchAndDevelopment | F138: 45986.119 | G138: =VLOOKUP(D138,MAP!B:C,2,0) -> Operating Expenses | H138: =VLOOKUP(D138,MAP!B:G,4,0) -> R&D
A139: APA | B139: 39447 | C139: USD | D139: researchAndDevelopment | F139: 45986.119 | G139: =VLOOKUP(D139,MAP!B:C,2,0) -> Operating Expenses | H139: =VLOOKUP(D139,MAP!B:G,4,0) -> R&D
A140: APA | B140: 39082 | C140: USD | D140: researchAndDevelopment | F140: 45986.119 | G140: =VLOOKUP(D140,MAP!B:C,2,0) -> Operating Expenses | H140: =VLOOKUP(D140,MAP!B:G,4,0) -> R&D
A141: APA | B141: 38717 | C141: USD | D141: researchAndDevelopment | F141: 45986.119 | G141: =VLOOKUP(D141,MAP!B:C,2,0) -> Operating Expenses | H141: =VLOOKUP(D141,MAP!B:G,4,0) -> R&D
A142: APA | B142: 45657 | C142: USD | D142: operatingExpenses | E142: 1103000000 | F142: 45986.119 | G142: =VLOOKUP(D142,MAP!B:C,2,0) -> Operating Expenses | H142: =VLOOKUP(D142,MAP!B:G,4,0) -> OPEX
A143: APA | B143: 45291 | C143: USD | D143: operatingExpenses | E143: 869000000 | F143: 45986.119 | G143: =VLOOKUP(D143,MAP!B:C,2,0) -> Operating Expenses | H143: =VLOOKUP(D143,MAP!B:G,4,0) -> OPEX
A144: APA | B144: 44926 | C144: USD | D144: operatingExpenses | E144: 1173000000 | F144: 45986.119 | G144: =VLOOKUP(D144,MAP!B:C,2,0) -> Operating Expenses | H144: =VLOOKUP(D144,MAP!B:G,4,0) -> OPEX
A145: APA | B145: 44561 | C145: USD | D145: operatingExpenses | E145: 848000000 | F145: 45986.119 | G145: =VLOOKUP(D145,MAP!B:C,2,0) -> Operating Expenses | H145: =VLOOKUP(D145,MAP!B:G,4,0) -> OPEX
A146: APA | B146: 44196 | C146: USD | D146: operatingExpenses | E146: 732000000 | F146: 45986.119 | G146: =VLOOKUP(D146,MAP!B:C,2,0) -> Operating Expenses | H146: =VLOOKUP(D146,MAP!B:G,4,0) -> OPEX
A147: APA | B147: 43830 | C147: USD | D147: operatingExpenses | E147: 1471000000 | F147: 45986.119 | G147: =VLOOKUP(D147,MAP!B:C,2,0) -> Operating Expenses | H147: =VLOOKUP(D147,MAP!B:G,4,0) -> OPEX
...
