Workbook

Sheet Positions
A1: Chapter | B1: Name | C1: Ticker | D1: Date | E1: Volume | F1: Price | G1: Value | H1: Expected Return QoQ% | I1: Volatility | J1: Ranking | K1: Mix % | L1: W/Avg Volatility | M1: Target Price | N1: Target Value | O1: Close Price | P1: Actual Value | Q1: Actual P&L | R1: Tolerance | S1: Unit Profit | T1: Unit Half Loss | U1: Balance Risk | V1: Normalized Risk | W1: Risk Mix | X1: Normalized Risk %
A2: Technology | B2: TSMC | C2: TSM | D2: =IF(ISERROR(VLOOKUP(C2,[1]Sheet1!$C:$C,1,0)),TODAY(),_xlfn.MINIFS([1]Sheet1!$F:$F,[1]Sheet1!$C:$C,C2)) -> 45716.856 | E2: =IFERROR(VLOOKUP(C2,'PBI Open Positions'!A:J,4,0),1E-32) -> 0.5547 | F2: =IFERROR(VLOOKUP(C2,'PBI Open Positions'!A:J,5,0),VLOOKUP(C2,'Stock Selection'!C:H,6,0)) -> 160.52 | G2: =E2*F2 -> 89.040444 | H2: =227.4/F2-1 -> 0.4166459 | I2: 0.37 | J2: =IFERROR(H2/I2,"") -> 1.12607 | K2: =IFERROR(J2/SUBTOTAL(9,$J$2:$J$1048576),"") -> 0.29277227 | L2: =I2*G2 -> 32.944964 | M2: =F2/(1-(F2*(1+H2)-F2)/(F2*(1+H2))) -> 227.4 | N2: =M2*E2 -> 126.13878 | O2: =IFERROR(VLOOKUP(C2,'PBI Open Positions'!A:F,6,0),VLOOKUP(Positions!C2,'Stock Selection'!C:H,6,0)) -> 220.05 | P2: =IFERROR(O2*E2,G2) -> 122.06173 | Q2: =P2-G2 -> 33.021291 | R2: =F2/(1+I2-H2) -> 168.37395 | S2: =M2-F2 -> 66.88 | T2: =0.5*(R2-F2) -> 3.9269774 | U2: =S2+T2 -> 70.806977 | V2: =SUBTOTAL(4,$U$2:$U$10000)-U2 -> -41.277042 | W2: =IFERROR((SUBTOTAL(109,$V$2:$V$1048576)/V2)/SUBTOTAL(109,$V$2:$V$1048576),0) -> 0 | X2: =V2/MAX($V$2:$V$28) -> -0.23902995
A3: ETF | B3: Vanguard Bonds | C3: BND | D3: =IF(ISERROR(VLOOKUP(C3,[1]Sheet1!$C:$C,1,0)),TODAY(),_xlfn.MINIFS([1]Sheet1!$F:$F,[1]Sheet1!$C:$C,C3)) -> 45743.774 | E3: =IFERROR(VLOOKUP(C3,'PBI Open Positions'!A:J,4,0),1E-32) -> 2 | F3: =IFERROR(VLOOKUP(C3,'PBI Open Positions'!A:J,5,0),VLOOKUP(C3,'Stock Selection'!C:H,6,0)) -> 73.5 | G3: =E3*F3 -> 147 | H3: 0.045 | I3: 0.165 | J3: =IFERROR(H3/I3,"") -> 0.27272727 | K3: =IFERROR(J3/SUBTOTAL(9,$J$2:$J$1048576),"") -> 0.070907655 | L3: =I3*G3 -> 24.255 | M3: =F3/(1-(F3*(1+H3)-F3)/(F3*(1+H3))) -> 76.8075 | N3: =M3*E3 -> 153.615 | O3: =IFERROR(VLOOKUP(C3,'PBI Open Positions'!A:F,6,0),VLOOKUP(Positions!C3,'Stock Selection'!C:H,6,0)) -> 73.28 | P3: =IFERROR(O3*E3,G3) -> 146.56 | Q3: =P3-G3 -> -0.44 | R3: =F3/(1+I3-H3) -> 65.625 | S3: =M3-F3 -> 3.3075 | T3: =0.5*(R3-F3) -> -3.9375 | U3: =S3+T3 -> -0.63 | V3: =SUBTOTAL(4,$U$2:$U$10000)-U3 -> 30.159936 | W3: =IFERROR((SUBTOTAL(109,$V$2:$V$1048576)/V3)/SUBTOTAL(109,$V$2:$V$1048576),0) -> 0 | X3: =V3/MAX($V$2:$V$28) -> 0.17465224
A4: ETF | B4: Emergin Markets | C4: VWO | D4: =IF(ISERROR(VLOOKUP(C4,[1]Sheet1!$C:$C,1,0)),TODAY(),_xlfn.MINIFS([1]Sheet1!$F:$F,[1]Sheet1!$C:$C,C4)) -> 45686.833 | E4: =IFERROR(VLOOKUP(C4,'PBI Open Positions'!A:J,4,0),1E-32) -> 4 | F4: =IFERROR(VLOOKUP(C4,'PBI Open Positions'!A:J,5,0),VLOOKUP(C4,'Stock Selection'!C:H,6,0)) -> 45.61 | G4: =E4*F4 -> 182.44 | H4: 0.083 | I4: 0.168 | J4: =IFERROR(H4/I4,"") -> 0.49404762 | K4: =IFERROR(J4/SUBTOTAL(9,$J$2:$J$1048576),"") -> 0.12844978 | L4: =I4*G4 -> 30.64992 | M4: =F4/(1-(F4*(1+H4)-F4)/(F4*(1+H4))) -> 49.39563 | N4: =M4*E4 -> 197.58252 | O4: =IFERROR(VLOOKUP(C4,'PBI Open Positions'!A:F,6,0),VLOOKUP(Positions!C4,'Stock Selection'!C:H,6,0)) -> 49.01 | P4: =IFERROR(O4*E4,G4) -> 196.04 | Q4: =P4-G4 -> 13.6 | R4: =F4/(1+I4-H4) -> 42.036866 | S4: =M4-F4 -> 3.78563 | T4: =0.5*(R4-F4) -> -1.7865668 | U4: =S4+T4 -> 1.9990632 | V4: =SUBTOTAL(4,$U$2:$U$10000)-U4 -> 27.530872 | W4: =IFERROR((SUBTOTAL(109,$V$2:$V$1048576)/V4)/SUBTOTAL(109,$V$2:$V$1048576),0) -> 0 | X4: =V4/MAX($V$2:$V$28) -> 0.15942768
A5: Energy & Utilities | B5: APA | C5: APA | D5: =IF(ISERROR(VLOOKUP(C5,[1]Sheet1!$C:$C,1,0)),TODAY(),_xlfn.MINIFS([1]Sheet1!$F:$F,[1]Sheet1!$C:$C,C5)) -> 45632.877 | E5: =IFERROR(VLOOKUP(C5,'PBI Open Positions'!A:J,4,0),1E-32) -> 6.8599 | F5: =IFERROR(VLOOKUP(C5,'PBI Open Positions'!A:J,5,0),VLOOKUP(C5,'Stock Selection'!C:H,6,0)) -> 18.94 | G5: =E5*F5 -> 129.92651 | H5: =M5/F5-1 -> 0.40337909 | I5: 0.4029 | J5: =IFERROR(H5/I5,"") -> 1.0011891 | K5: =IFERROR(J5/SUBTOTAL(9,$J$2:$J$1048576),"") -> 0.2603039 | L5: =I5*G5 -> 52.347389 | M5: 26.58 | N5: =M5*E5 -> 182.33614 | O5: =IFERROR(VLOOKUP(C5,'PBI Open Positions'!A:F,6,0),VLOOKUP(Positions!C5,'Stock Selection'!C:H,6,0)) -> 18.17 | P5: =IFERROR(O5*E5,G5) -> 124.64438 | Q5: =P5-G5 -> -5.282123 | R5: =F5/(1+I5-H5) -> 18.949078 | S5: =M5-F5 -> 7.64 | T5: =0.5*(R5-F5) -> 0.0045391747 | U5: =S5+T5 -> 7.6445392 | V5: =SUBTOTAL(4,$U$2:$U$10000)-U5 -> 21.885396 | W5: =IFERROR((SUBTOTAL(109,$V$2:$V$1048576)/V5)/SUBTOTAL(109,$V$2:$V$1048576),0) -> 0 | X5: =V5/MAX($V$2:$V$28) -> 0.12673547
A6: Energy & Utilities | B6: First Solar | C6: FSLR | D6: =IF(ISERROR(VLOOKUP(C6,[1]Sheet1!$C:$C,1,0)),TODAY(),_xlfn.MINIFS([1]Sheet1!$F:$F,[1]Sheet1!$C:$C,C6)) -> 45727.872 | E6: =IFERROR(VLOOKUP(C6,'PBI Open Positions'!A:J,4,0),1E-32) -> 0.497 | F6: =IFERROR(VLOOKUP(C6,'PBI Open Positions'!A:J,5,0),VLOOKUP(C6,'Stock Selection'!C:H,6,0)) -> 137.42 | G6: =E6*F6 -> 68.29774 | H6: =196.02/F6-1 -> 0.42642992 | I6: 0.5203 | J6: =IFERROR(H6/I6,"") -> 0.81958471 | K6: =IFERROR(J6/SUBTOTAL(9,$J$2:$J$1048576),"") -> 0.21308771 | L6: =I6*G6 -> 35.535314 | M6: =F6/(1-(F6*(1+H6)-F6)/(F6*(1+H6))) -> 196.02 | N6: =M6*E6 -> 97.42194 | O6: =IFERROR(VLOOKUP(C6,'PBI Open Positions'!A:F,6,0),VLOOKUP(Positions!C6,'Stock Selection'!C:H,6,0)) -> 150.54 | P6: =IFERROR(O6*E6,G6) -> 74.81838 | Q6: =P6-G6 -> 6.52064 | R6: =F6/(1+I6-H6) -> 125.62735 | S6: =M6-F6 -> 58.6 | T6: =0.5*(R6-F6) -> -5.8963246 | U6: =S6+T6 -> 52.703675 | V6: =SUBTOTAL(4,$U$2:$U$10000)-U6 -> -23.17374 | W6: =IFERROR((SUBTOTAL(109,$V$2:$V$1048576)/V6)/SUBTOTAL(109,$V$2:$V$1048576),0) -> 0 | X6: =V6/MAX($V$2:$V$28) -> -0.1341961
A7: ETF | B7: Bitcoin ETF | C7: VBTC.DE | D7: =IF(ISERROR(VLOOKUP(C7,[1]Sheet1!$C:$C,1,0)),TODAY(),_xlfn.MINIFS([1]Sheet1!$F:$F,[1]Sheet1!$C:$C,C7)) -> 45833 | E7: =IFERROR(VLOOKUP(C7,'PBI Open Positions'!A:J,4,0),1E-32) -> 1e-32 | F7: =IFERROR(VLOOKUP(C7,'PBI Open Positions'!A:J,5,0),VLOOKUP(C7,'Stock Selection'!C:H,6,0)) -> 48.34 | G7: =E7*F7 -> 4.834e-31 | H7: 0.1 | I7: 0.2 | J7: =IFERROR(H7/I7,"") -> 0.5 | K7: =IFERROR(J7/SUBTOTAL(9,$J$2:$J$1048576),"") -> 0.12999737 | L7: =I7*G7 -> 9.668e-32 | M7: =F7/(1-(F7*(1+H7)-F7)/(F7*(1+H7))) -> 53.174 | N7: =M7*E7 -> 5.3174e-31 | O7: =IFERROR(VLOOKUP(C7,'PBI Open Positions'!A:F,6,0),VLOOKUP(Positions!C7,'Stock Selection'!C:H,6,0)) -> 48.34 | P7: =IFERROR(O7*E7,G7) -> 4.834e-31 | Q7: =P7-G7 -> 0 | R7: =F7/(1+I7-H7) -> 43.945455 | S7: =M7-F7 -> 4.834 | T7: =0.5*(R7-F7) -> -2.1972727 | U7: =S7+T7 -> 2.6367273 | V7: =SUBTOTAL(4,$U$2:$U$10000)-U7 -> 26.893208 | W7: =IFERROR((SUBTOTAL(109,$V$2:$V$1048576)/V7)/SUBTOTAL(109,$V$2:$V$1048576),0) -> 0 | X7: =V7/MAX($V$2:$V$28) -> 0.15573505
A8: Consumer Defensive | B8: Altaria | C8: MO | D8: =IF(ISERROR(VLOOKUP(C8,[1]Sheet1!$C:$C,1,0)),TODAY(),_xlfn.MINIFS([1]Sheet1!$F:$F,[1]Sheet1!$C:$C,C8)) -> 45518.844 | E8: =IFERROR(VLOOKUP(C8,'PBI Open Positions'!A:J,4,0),1E-32) -> 2.3939 | F8: =IFERROR(VLOOKUP(C8,'PBI Open Positions'!A:J,5,0),VLOOKUP(C8,'Stock Selection'!C:H,6,0)) -> 54.2 | G8: =E8*F8 -> 129.74938 | H8: =16.68%+7%/4 -> 0.1843 | I8: 0.1998 | J8: =IFERROR(H8/I8,"") -> 0.92242242 | K8: =IFERROR(J8/SUBTOTAL(9,$J$2:$J$1048576),"") -> 0.23982497 | L8: =I8*G8 -> 25.923926 | M8: =F8/(1-(F8*(1+H8)-F8)/(F8*(1+H8))) -> 64.18906 | N8: =M8*E8 -> 153.66219 | O8: =IFERROR(VLOOKUP(C8,'PBI Open Positions'!A:F,6,0),VLOOKUP(Positions!C8,'Stock Selection'!C:H,6,0)) -> 59.93 | P8: =IFERROR(O8*E8,G8) -> 143.46643 | Q8: =P8-G8 -> 13.717047 | R8: =F8/(1+I8-H8) -> 53.372723 | S8: =M8-F8 -> 9.98906 | T8: =0.5*(R8-F8) -> -0.4136386 | U8: =S8+T8 -> 9.5754214 | V8: =SUBTOTAL(4,$U$2:$U$10000)-U8 -> 19.954514 | W8: =IFERROR((SUBTOTAL(109,$V$2:$V$1048576)/V8)/SUBTOTAL(109,$V$2:$V$1048576),0) -> 0 | X8: =V8/MAX($V$2:$V$28) -> 0.11555398
A9: Consumer Defensive | B9: Pepsi | C9: PEP | D9: =IF(ISERROR(VLOOKUP(C9,[1]Sheet1!$C:$C,1,0)),TODAY(),_xlfn.MINIFS([1]Sheet1!$F:$F,[1]Sheet1!$C:$C,C9)) -> 45460.885 | E9: =IFERROR(VLOOKUP(C9,'PBI Open Positions'!A:J,4,0),1E-32) -> 0.8085 | F9: =IFERROR(VLOOKUP(C9,'PBI Open Positions'!A:J,5,0),VLOOKUP(C9,'Stock Selection'!C:H,6,0)) -> 147.19 | G9: =E9*F9 -> 119.00311 | H9: 0.0672 | I9: 0.1644 | J9: =IFERROR(H9/I9,"") -> 0.40875912 | K9: =IFERROR(J9/SUBTOTAL(9,$J$2:$J$1048576),"") -> 0.10627522 | L9: =I9*G9 -> 19.564112 | M9: =F9/(1-(F9*(1+H9)-F9)/(F9*(1+H9))) -> 157.08117 | N9: =M9*E9 -> 127.00012 | O9: =IFERROR(VLOOKUP(C9,'PBI Open Positions'!A:F,6,0),VLOOKUP(Positions!C9,'Stock Selection'!C:H,6,0)) -> 131.08 | P9: =IFERROR(O9*E9,G9) -> 105.97818 | Q9: =P9-G9 -> -13.024935 | R9: =F9/(1+I9-H9) -> 134.15057 | S9: =M9-F9 -> 9.891168 | T9: =0.5*(R9-F9) -> -6.5197175 | U9: =S9+T9 -> 3.3714505 | V9: =SUBTOTAL(4,$U$2:$U$10000)-U9 -> 26.158485 | W9: =IFERROR((SUBTOTAL(109,$V$2:$V$1048576)/V9)/SUBTOTAL(109,$V$2:$V$1048576),0) -> 0 | X9: =V9/MAX($V$2:$V$28) -> 0.15148036
A10: Energy & Utilities | B10: YPF | C10: YPF | D10: =IF(ISERROR(VLOOKUP(C10,[1]Sheet1!$C:$C,1,0)),TODAY(),_xlfn.MINIFS([1]Sheet1!$F:$F,[1]Sheet1!$C:$C,C10)) -> 45663.738 | E10: =IFERROR(VLOOKUP(C10,'PBI Open Positions'!A:J,4,0),1E-32) -> 2.4948 | F10: =IFERROR(VLOOKUP(C10,'PBI Open Positions'!A:J,5,0),VLOOKUP(C10,'Stock Selection'!C:H,6,0)) -> 36.06 | G10: =E10*F10 -> 89.962488 | H10: =M10/F10-1 -> 0.38657793 | I10: 0.5311 | J10: =IFERROR(H10/I10,"") -> 0.72788161 | K10: =IFERROR(J10/SUBTOTAL(9,$J$2:$J$1048576),"") -> 0.18924539 | L10: =I10*G10 -> 47.779077 | M10: 50 | N10: =M10*E10 -> 124.74 | O10: =IFERROR(VLOOKUP(C10,'PBI Open Positions'!A:F,6,0),VLOOKUP(Positions!C10,'Stock Selection'!C:H,6,0)) -> 34.37 | P10: =IFERROR(O10*E10,G10) -> 85.746276 | Q10: =P10-G10 -> -4.216212 | R10: =F10/(1+I10-H10) -> 31.506601 | S10: =M10-F10 -> 13.94 | T10: =0.5*(R10-F10) -> -2.2766996 | U10: =S10+T10 -> 11.6633 | V10: =SUBTOTAL(4,$U$2:$U$10000)-U10 -> 17.866635 | W10: =IFERROR((SUBTOTAL(109,$V$2:$V$1048576)/V10)/SUBTOTAL(109,$V$2:$V$1048576),0) -> 0 | X10: =V10/MAX($V$2:$V$28) -> 0.10346335
A11: Technology | B11: Microsoft | C11: MSFT | D11: =IF(ISERROR(VLOOKUP(C11,[1]Sheet1!$C:$C,1,0)),TODAY(),_xlfn.MINIFS([1]Sheet1!$F:$F,[1]Sheet1!$C:$C,C11)) -> 45695.856 | E11: =IFERROR(VLOOKUP(C11,'PBI Open Positions'!A:J,4,0),1E-32) -> 0.001 | F11: =IFERROR(VLOOKUP(C11,'PBI Open Positions'!A:J,5,0),VLOOKUP(C11,'Stock Selection'!C:H,6,0)) -> 410 | G11: =E11*F11 -> 0.41 | H11: 0.15 | I11: 0.1963 | J11: =IFERROR(H11/I11,"") -> 0.76413653 | K11: =IFERROR(J11/SUBTOTAL(9,$J$2:$J$1048576),"") -> 0.19867147 | L11: =I11*G11 -> 0.080483 | M11: =F11/(1-(F11*(1+H11)-F11)/(F11*(1+H11))) -> 471.5 | N11: =M11*E11 -> 0.4715 | O11: =IFERROR(VLOOKUP(C11,'PBI Open Positions'!A:F,6,0),VLOOKUP(Positions!C11,'Stock Selection'!C:H,6,0)) -> 490 | P11: =IFERROR(O11*E11,G11) -> 0.49 | Q11: =P11-G11 -> 0.08 | R11: =F11/(1+I11-H11) -> 391.85702 | S11: =M11-F11 -> 61.5 | T11: =0.5*(R11-F11) -> -9.07149 | U11: =S11+T11 -> 52.42851 | V11: =SUBTOTAL(4,$U$2:$U$10000)-U11 -> -22.898574 | W11: =IFERROR((SUBTOTAL(109,$V$2:$V$1048576)/V11)/SUBTOTAL(109,$V$2:$V$1048576),0) -> 0 | X11: =V11/MAX($V$2:$V$28) -> -0.13260265
A12: Financial Services | B12: ING Group NV | C12: ING | D12: =IF(ISERROR(VLOOKUP(C12,[1]Sheet1!$C:$C,1,0)),TODAY(),_xlfn.MINIFS([1]Sheet1!$F:$F,[1]Sheet1!$C:$C,C12)) -> 45623.75 | E12: =IFERROR(VLOOKUP(C12,'PBI Open Positions'!A:J,4,0),1E-32) -> 4.8753 | F12: =IFERROR(VLOOKUP(C12,'PBI Open Positions'!A:J,5,0),VLOOKUP(C12,'Stock Selection'!C:H,6,0)) -> 17.56 | G12: =E12*F12 -> 85.610268 | H12: 0.0902 | I12: 0.2789 | J12: =IFERROR(H12/I12,"") -> 0.32341341 | K12: =IFERROR(J12/SUBTOTAL(9,$J$2:$J$1048576),"") -> 0.084085784 | L12: =I12*G12 -> 23.876704 | M12: =F12/(1-(F12*(1+H12)-F12)/(F12*(1+H12))) -> 19.143912 | N12: =M12*E12 -> 93.332314 | O12: =IFERROR(VLOOKUP(C12,'PBI Open Positions'!A:F,6,0),VLOOKUP(Positions!C12,'Stock Selection'!C:H,6,0)) -> 21.35 | P12: =IFERROR(O12*E12,G12) -> 104.08766 | Q12: =P12-G12 -> 18.477387 | R12: =F12/(1+I12-H12) -> 14.77244 | S12: =M12-F12 -> 1.583912 | T12: =0.5*(R12-F12) -> -1.3937798 | U12: =S12+T12 -> 0.19013224 | V12: =SUBTOTAL(4,$U$2:$U$10000)-U12 -> 29.339803 | W12: =IFERROR((SUBTOTAL(109,$V$2:$V$1048576)/V12)/SUBTOTAL(109,$V$2:$V$1048576),0) -> 0 | X12: =V12/MAX($V$2:$V$28) -> 0.16990296
A13: Consumer Defensive | B13: Albertson Companies | C13: ACI | D13: =IF(ISERROR(VLOOKUP(C13,[1]Sheet1!$C:$C,1,0)),TODAY(),_xlfn.MINIFS([1]Sheet1!$F:$F,[1]Sheet1!$C:$C,C13)) -> 45693.855 | E13: =IFERROR(VLOOKUP(C13,'PBI Open Positions'!A:J,4,0),1E-32) -> 6 | F13: =IFERROR(VLOOKUP(C13,'PBI Open Positions'!A:J,5,0),VLOOKUP(C13,'Stock Selection'!C:H,6,0)) -> 21.05 | G13: =E13*F13 -> 126.3 | H13: 0.2 | I13: 0.2 | J13: =IFERROR(H13/I13,"") -> 1 | K13: =IFERROR(J13/SUBTOTAL(9,$J$2:$J$1048576),"") -> 0.25999474 | L13: =I13*G13 -> 25.26 | M13: =F13/(1-(F13*(1+H13)-F13)/(F13*(1+H13))) -> 25.26 | N13: =M13*E13 -> 151.56 | O13: =IFERROR(VLOOKUP(C13,'PBI Open Positions'!A:F,6,0),VLOOKUP(Positions!C13,'Stock Selection'!C:H,6,0)) -> 21.68 | P13: =IFERROR(O13*E13,G13) -> 130.08 | Q13: =P13-G13 -> 3.78 | R13: =F13/(1+I13-H13) -> 21.05 | S13: =M13-F13 -> 4.21 | T13: =0.5*(R13-F13) -> 0 | U13: =S13+T13 -> 4.21 | V13: =SUBTOTAL(4,$U$2:$U$10000)-U13 -> 25.319936 | W13: =IFERROR((SUBTOTAL(109,$V$2:$V$1048576)/V13)/SUBTOTAL(109,$V$2:$V$1048576),0) -> 0 | X13: =V13/MAX($V$2:$V$28) -> 0.14662443
A14: Financial Services | B14: Master Card | C14: MA | D14: =IF(ISERROR(VLOOKUP(C14,[1]Sheet1!$C:$C,1,0)),TODAY(),_xlfn.MINIFS([1]Sheet1!$F:$F,[1]Sheet1!$C:$C,C14)) -> 45645.901 | E14: =IFERROR(VLOOKUP(C14,'PBI Open Positions'!A:J,4,0),1E-32) -> 0.0781 | F14: =IFERROR(VLOOKUP(C14,'PBI Open Positions'!A:J,5,0),VLOOKUP(C14,'Stock Selection'!C:H,6,0)) -> 518.05 | G14: =E14*F14 -> 40.459705 | H14: 0.0959 | I14: 0.1865 | J14: =IFERROR(H14/I14,"") -> 0.51420912 | K14: =IFERROR(J14/SUBTOTAL(9,$J$2:$J$1048576),"") -> 0.13369166 | L14: =I14*G14 -> 7.545735 | M14: =F14/(1-(F14*(1+H14)-F14)/(F14*(1+H14))) -> 567.731 | N14: =M14*E14 -> 44.339791 | O14: =IFERROR(VLOOKUP(C14,'PBI Open Positions'!A:F,6,0),VLOOKUP(Positions!C14,'Stock Selection'!C:H,6,0)) -> 556.34 | P14: =IFERROR(O14*E14,G14) -> 43.450154 | Q14: =P14-G14 -> 2.990449 | R14: =F14/(1+I14-H14) -> 475.01375 | S14: =M14-F14 -> 49.680995 | T14: =0.5*(R14-F14) -> -21.518123 | U14: =S14+T14 -> 28.162872 | V14: =SUBTOTAL(4,$U$2:$U$10000)-U14 -> 1.3670636 | W14: =IFERROR((SUBTOTAL(109,$V$2:$V$1048576)/V14)/SUBTOTAL(109,$V$2:$V$1048576),0) -> 0 | X14: =V14/MAX($V$2:$V$28) -> 0.0079164863
A15: Energy & Utilities | B15: NextEra Energy | C15: NEE | D15: =IF(ISERROR(VLOOKUP(C15,[1]Sheet1!$C:$C,1,0)),TODAY(),_xlfn.MINIFS([1]Sheet1!$F:$F,[1]Sheet1!$C:$C,C15)) -> 45511.86 | E15: =IFERROR(VLOOKUP(C15,'PBI Open Positions'!A:J,4,0),1E-32) -> 0.9669 | F15: =IFERROR(VLOOKUP(C15,'PBI Open Positions'!A:J,5,0),VLOOKUP(C15,'Stock Selection'!C:H,6,0)) -> 72.38 | G15: =E15*F15 -> 69.984222 | H15: 0.05 | I15: 0.2786 | J15: =IFERROR(H15/I15,"") -> 0.17946877 | K15: =IFERROR(J15/SUBTOTAL(9,$J$2:$J$1048576),"") -> 0.046660936 | L15: =I15*G15 -> 19.497604 | M15: =F15/(1-(F15*(1+H15)-F15)/(F15*(1+H15))) -> 75.999 | N15: =M15*E15 -> 73.483433 | O15: =IFERROR(VLOOKUP(C15,'PBI Open Positions'!A:F,6,0),VLOOKUP(Positions!C15,'Stock Selection'!C:H,6,0)) -> 71.42 | P15: =IFERROR(O15*E15,G15) -> 69.055998 | Q15: =P15-G15 -> -0.928224 | R15: =F15/(1+I15-H15) -> 58.912583 | S15: =M15-F15 -> 3.619 | T15: =0.5*(R15-F15) -> -6.7337083 | U15: =S15+T15 -> -3.1147083 | V15: =SUBTOTAL(4,$U$2:$U$10000)-U15 -> 32.644644 | W15: =IFERROR((SUBTOTAL(109,$V$2:$V$1048576)/V15)/SUBTOTAL(109,$V$2:$V$1048576),0) -> 0 | X15: =V15/MAX($V$2:$V$28) -> 0.18904086
A16: Consumer Defensive | B16: Kimberly Clark | C16: KMB | D16: =IF(ISERROR(VLOOKUP(C16,[1]Sheet1!$C:$C,1,0)),TODAY(),_xlfn.MINIFS([1]Sheet1!$F:$F,[1]Sheet1!$C:$C,C16)) -> 45544.652 | E16: =IFERROR(VLOOKUP(C16,'PBI Open Positions'!A:J,4,0),1E-32) -> 0.4774 | F16: =IFERROR(VLOOKUP(C16,'PBI Open Positions'!A:J,5,0),VLOOKUP(C16,'Stock Selection'!C:H,6,0)) -> 134.88 | G16: =E16*F16 -> 64.391712 | H16: 0.07 | I16: 0.1834 | J16: =IFERROR(H16/I16,"") -> 0.38167939 | K16: =IFERROR(J16/SUBTOTAL(9,$J$2:$J$1048576),"") -> 0.099234632 | L16: =I16*G16 -> 11.80944 | M16: =F16/(1-(F16*(1+H16)-F16)/(F16*(1+H16))) -> 144.3216 | N16: =M16*E16 -> 68.899132 | O16: =IFERROR(VLOOKUP(C16,'PBI Open Positions'!A:F,6,0),VLOOKUP(Positions!C16,'Stock Selection'!C:H,6,0)) -> 129.91 | P16: =IFERROR(O16*E16,G16) -> 62.019034 | Q16: =P16-G16 -> -2.372678 | R16: =F16/(1+I16-H16) -> 121.14245 | S16: =M16-F16 -> 9.4416 | T16: =0.5*(R16-F16) -> -6.8687767 | U16: =S16+T16 -> 2.5728233 | V16: =SUBTOTAL(4,$U$2:$U$10000)-U16 -> 26.957112 | W16: =IFERROR((SUBTOTAL(109,$V$2:$V$1048576)/V16)/SUBTOTAL(109,$V$2:$V$1048576),0) -> 0 | X16: =V16/MAX($V$2:$V$28) -> 0.15610511
A17: Consumer Defensive | B17: Ingredion | C17: INGR | D17: =IF(ISERROR(VLOOKUP(C17,[1]Sheet1!$C:$C,1,0)),TODAY(),_xlfn.MINIFS([1]Sheet1!$F:$F,[1]Sheet1!$C:$C,C17)) -> 45580.706 | E17: =IFERROR(VLOOKUP(C17,'PBI Open Positions'!A:J,4,0),1E-32) -> 0.3486 | F17: =IFERROR(VLOOKUP(C17,'PBI Open Positions'!A:J,5,0),VLOOKUP(C17,'Stock Selection'!C:H,6,0)) -> 131.93 | G17: =E17*F17 -> 45.990798 | H17: 0.1202 | I17: 0.3371 | J17: =IFERROR(H17/I17,"") -> 0.35657075 | K17: =IFERROR(J17/SUBTOTAL(9,$J$2:$J$1048576),"") -> 0.092706518 | L17: =I17*G17 -> 15.503498 | M17: =F17/(1-(F17*(1+H17)-F17)/(F17*(1+H17))) -> 147.78799 | N17: =M17*E17 -> 51.518892 | O17: =IFERROR(VLOOKUP(C17,'PBI Open Positions'!A:F,6,0),VLOOKUP(Positions!C17,'Stock Selection'!C:H,6,0)) -> 137.46 | P17: =IFERROR(O17*E17,G17) -> 47.918556 | Q17: =P17-G17 -> 1.927758 | R17: =F17/(1+I17-H17) -> 108.41482 | S17: =M17-F17 -> 15.857986 | T17: =0.5*(R17-F17) -> -11.757588 | U17: =S17+T17 -> 4.1003983 | V17: =SUBTOTAL(4,$U$2:$U$10000)-U17 -> 25.429537 | W17: =IFERROR((SUBTOTAL(109,$V$2:$V$1048576)/V17)/SUBTOTAL(109,$V$2:$V$1048576),0) -> 0 | X17: =V17/MAX($V$2:$V$28) -> 0.14725912
A18: ETF | B18: Robotics & AI | C18: BOTZ.L | D18: =IF(ISERROR(VLOOKUP(C18,[1]Sheet1!$C:$C,1,0)),TODAY(),_xlfn.MINIFS([1]Sheet1!$F:$F,[1]Sheet1!$C:$C,C18)) -> 45482.713 | E18: =IFERROR(VLOOKUP(C18,'PBI Open Positions'!A:J,4,0),1E-32) -> 2 | F18: =IFERROR(VLOOKUP(C18,'PBI Open Positions'!A:J,5,0),VLOOKUP(C18,'Stock Selection'!C:H,6,0)) -> 20.93 | G18: =E18*F18 -> 41.86 | H18: 0.035 | I18: 0.165 | J18: =IFERROR(H18/I18,"") -> 0.21212121 | K18: =IFERROR(J18/SUBTOTAL(9,$J$2:$J$1048576),"") -> 0.055150399 | L18: =I18*G18 -> 6.9069 | M18: =F18/(1-(F18*(1+H18)-F18)/(F18*(1+H18))) -> 21.66255 | N18: =M18*E18 -> 43.3251 | O18: =IFERROR(VLOOKUP(C18,'PBI Open Positions'!A:F,6,0),VLOOKUP(Positions!C18,'Stock Selection'!C:H,6,0)) -> 20.58 | P18: =IFERROR(O18*E18,G18) -> 41.16 | Q18: =P18-G18 -> -0.7 | R18: =F18/(1+I18-H18) -> 18.522124 | S18: =M18-F18 -> 0.73255 | T18: =0.5*(R18-F18) -> -1.2039381 | U18: =S18+T18 -> -0.47138805 | V18: =SUBTOTAL(4,$U$2:$U$10000)-U18 -> 30.001324 | W18: =IFERROR((SUBTOTAL(109,$V$2:$V$1048576)/V18)/SUBTOTAL(109,$V$2:$V$1048576),0) -> 0 | X18: =V18/MAX($V$2:$V$28) -> 0.17373374
A19: ETF | B19: Batterey Value-Chain | C19: BATT.AS | D19: =IF(ISERROR(VLOOKUP(C19,[1]Sheet1!$C:$C,1,0)),TODAY(),_xlfn.MINIFS([1]Sheet1!$F:$F,[1]Sheet1!$C:$C,C19)) -> 45484.679 | E19: =IFERROR(VLOOKUP(C19,'PBI Open Positions'!A:J,4,0),1E-32) -> 2 | F19: =IFERROR(VLOOKUP(C19,'PBI Open Positions'!A:J,5,0),VLOOKUP(C19,'Stock Selection'!C:H,6,0)) -> 17.51 | G19: =E19*F19 -> 35.02 | H19: 0.035 | I19: 0.165 | J19: =IFERROR(H19/I19,"") -> 0.21212121 | K19: =IFERROR(J19/SUBTOTAL(9,$J$2:$J$1048576),"") -> 0.055150399 | L19: =I19*G19 -> 5.7783 | M19: =F19/(1-(F19*(1+H19)-F19)/(F19*(1+H19))) -> 18.12285 | N19: =M19*E19 -> 36.2457 | O19: =IFERROR(VLOOKUP(C19,'PBI Open Positions'!A:F,6,0),VLOOKUP(Positions!C19,'Stock Selection'!C:H,6,0)) -> 17.56 | P19: =IFERROR(O19*E19,G19) -> 35.12 | Q19: =P19-G19 -> 0.1 | R19: =F19/(1+I19-H19) -> 15.495575 | S19: =M19-F19 -> 0.61285 | T19: =0.5*(R19-F19) -> -1.0072124 | U19: =S19+T19 -> -0.39436239 | V19: =SUBTOTAL(4,$U$2:$U$10000)-U19 -> 29.924298 | W19: =IFERROR((SUBTOTAL(109,$V$2:$V$1048576)/V19)/SUBTOTAL(109,$V$2:$V$1048576),0) -> 0 | X19: =V19/MAX($V$2:$V$28) -> 0.17328769
A20: Technology | B20: Google | C20: GOOGL | D20: =IF(ISERROR(VLOOKUP(C20,[1]Sheet1!$C:$C,1,0)),TODAY(),_xlfn.MINIFS([1]Sheet1!$F:$F,[1]Sheet1!$C:$C,C20)) -> 45734.856 | E20: =IFERROR(VLOOKUP(C20,'PBI Open Positions'!A:J,4,0),1E-32) -> 0.0282 | F20: =IFERROR(VLOOKUP(C20,'PBI Open Positions'!A:J,5,0),VLOOKUP(C20,'Stock Selection'!C:H,6,0)) -> 160.64 | G20: =E20*F20 -> 4.530048 | H20: =190.41/F20-1 -> 0.18532122 | I20: 0.2679 | J20: =IFERROR(H20/I20,"") -> 0.69175519 | K20: =IFERROR(J20/SUBTOTAL(9,$J$2:$J$1048576),"") -> 0.17985271 | L20: =I20*G20 -> 1.2135999 | M20: =F20/(1-(F20*(1+H20)-F20)/(F20*(1+H20))) -> 190.41 | N20: =M20*E20 -> 5.369562 | O20: =IFERROR(VLOOKUP(C20,'PBI Open Positions'!A:F,6,0),VLOOKUP(Positions!C20,'Stock Selection'!C:H,6,0)) -> 166.67 | P20: =IFERROR(O20*E20,G20) -> 4.700094 | Q20: =P20-G20 -> 0.170046 | R20: =F20/(1+I20-H20) -> 148.38643 | S20: =M20-F20 -> 29.77 | T20: =0.5*(R20-F20) -> -6.1267855 | U20: =S20+T20 -> 23.643215 | V20: =SUBTOTAL(4,$U$2:$U$10000)-U20 -> 5.886721 | W20: =IFERROR((SUBTOTAL(109,$V$2:$V$1048576)/V20)/SUBTOTAL(109,$V$2:$V$1048576),0) -> 0 | X20: =V20/MAX($V$2:$V$28) -> 0.034089231
A21: Healthcare | B21: Agios | C21: AGIO | D21: =IF(ISERROR(VLOOKUP(C21,[1]Sheet1!$C:$C,1,0)),TODAY(),_xlfn.MINIFS([1]Sheet1!$F:$F,[1]Sheet1!$C:$C,C21)) -> 45805.662 | E21: =IFERROR(VLOOKUP(C21,'PBI Open Positions'!A:J,4,0),1E-32) -> 0.0179 | F21: =IFERROR(VLOOKUP(C21,'PBI Open Positions'!A:J,5,0),VLOOKUP(C21,'Stock Selection'!C:H,6,0)) -> 30.73 | G21: =E21*F21 -> 0.550067 | H21: 0.2 | I21: 0.2 | J21: =IFERROR(H21/I21,"") -> 1 | K21: =IFERROR(J21/SUBTOTAL(9,$J$2:$J$1048576),"") -> 0.25999474 | L21: =I21*G21 -> 0.1100134 | M21: =F21/(1-(F21*(1+H21)-F21)/(F21*(1+H21))) -> 36.876 | N21: =M21*E21 -> 0.6600804 | O21: =IFERROR(VLOOKUP(C21,'PBI Open Positions'!A:F,6,0),VLOOKUP(Positions!C21,'Stock Selection'!C:H,6,0)) -> 33.52 | P21: =IFERROR(O21*E21,G21) -> 0.600008 | Q21: =P21-G21 -> 0.049941 | R21: =F21/(1+I21-H21) -> 30.73 | S21: =M21-F21 -> 6.146 | T21: =0.5*(R21-F21) -> 0 | U21: =S21+T21 -> 6.146 | V21: =SUBTOTAL(4,$U$2:$U$10000)-U21 -> 23.383936 | W21: =IFERROR((SUBTOTAL(109,$V$2:$V$1048576)/V21)/SUBTOTAL(109,$V$2:$V$1048576),0) -> 0 | X21: =V21/MAX($V$2:$V$28) -> 0.13541331
A22: Financial Services | B22: BARCLAYS | C22: BCS | D22: =IF(ISERROR(VLOOKUP(C22,[1]Sheet1!$C:$C,1,0)),TODAY(),_xlfn.MINIFS([1]Sheet1!$F:$F,[1]Sheet1!$C:$C,C22)) -> 45764.855 | E22: =IFERROR(VLOOKUP(C22,'PBI Open Positions'!A:J,4,0),1E-32) -> 4.8087 | F22: =IFERROR(VLOOKUP(C22,'PBI Open Positions'!A:J,5,0),VLOOKUP(C22,'Stock Selection'!C:H,6,0)) -> 16.64 | G22: =E22*F22 -> 80.016768 | H22: 0.1857 | I22: 0.346 | J22: =IFERROR(H22/I22,"") -> 0.5367052 | K22: =IFERROR(J22/SUBTOTAL(9,$J$2:$J$1048576),"") -> 0.13954053 | L22: =I22*G22 -> 27.685802 | M22: =F22/(1-(F22*(1+H22)-F22)/(F22*(1+H22))) -> 19.730048 | N22: =M22*E22 -> 94.875882 | O22: =IFERROR(VLOOKUP(C22,'PBI Open Positions'!A:F,6,0),VLOOKUP(Positions!C22,'Stock Selection'!C:H,6,0)) -> 18.25 | P22: =IFERROR(O22*E22,G22) -> 87.758775 | Q22: =P22-G22 -> 7.742007 | R22: =F22/(1+I22-H22) -> 14.341119 | S22: =M22-F22 -> 3.090048 | T22: =0.5*(R22-F22) -> -1.1494407 | U22: =S22+T22 -> 1.9406073 | V22: =SUBTOTAL(4,$U$2:$U$10000)-U22 -> 27.589328 | W22: =IFERROR((SUBTOTAL(109,$V$2:$V$1048576)/V22)/SUBTOTAL(109,$V$2:$V$1048576),0) -> 0 | X22: =V22/MAX($V$2:$V$28) -> 0.15976619
A23: Financial Services | B23: Visa | C23: V | D23: =IF(ISERROR(VLOOKUP(C23,[1]Sheet1!$C:$C,1,0)),TODAY(),_xlfn.MINIFS([1]Sheet1!$F:$F,[1]Sheet1!$C:$C,C23)) -> 45751.745 | E23: =IFERROR(VLOOKUP(C23,'PBI Open Positions'!A:J,4,0),1E-32) -> 0.0624 | F23: =IFERROR(VLOOKUP(C23,'PBI Open Positions'!A:J,5,0),VLOOKUP(C23,'Stock Selection'!C:H,6,0)) -> 339.74 | G23: =E23*F23 -> 21.199776 | H23: 0.1177 | I23: 0.1833 | J23: =IFERROR(H23/I23,"") -> 0.64211675 | K23: =IFERROR(J23/SUBTOTAL(9,$J$2:$J$1048576),"") -> 0.16694697 | L23: =I23*G23 -> 3.8859189 | M23: =F23/(1-(F23*(1+H23)-F23)/(F23*(1+H23))) -> 379.7274 | N23: =M23*E23 -> 23.69499 | O23: =IFERROR(VLOOKUP(C23,'PBI Open Positions'!A:F,6,0),VLOOKUP(Positions!C23,'Stock Selection'!C:H,6,0)) -> 351.6 | P23: =IFERROR(O23*E23,G23) -> 21.93984 | Q23: =P23-G23 -> 0.740064 | R23: =F23/(1+I23-H23) -> 318.82508 | S23: =M23-F23 -> 39.987398 | T23: =0.5*(R23-F23) -> -10.457462 | U23: =S23+T23 -> 29.529936 | V23: =SUBTOTAL(4,$U$2:$U$10000)-U23 -> 0 | W23: =IFERROR((SUBTOTAL(109,$V$2:$V$1048576)/V23)/SUBTOTAL(109,$V$2:$V$1048576),0) -> 0 | X23: =V23/MAX($V$2:$V$28) -> 0
A24: Consumer Defensive | B24: MSG | C24: DAR | D24: =IF(ISERROR(VLOOKUP(C24,[1]Sheet1!$C:$C,1,0)),TODAY(),_xlfn.MINIFS([1]Sheet1!$F:$F,[1]Sheet1!$C:$C,C24)) -> 45796.825 | E24: =IFERROR(VLOOKUP(C24,'PBI Open Positions'!A:J,4,0),1E-32) -> 0.1091 | F24: =IFERROR(VLOOKUP(C24,'PBI Open Positions'!A:J,5,0),VLOOKUP(C24,'Stock Selection'!C:H,6,0)) -> 33.64 | G24: =E24*F24 -> 3.670124 | H24: 0.07 | I24: 0.4 | J24: =IFERROR(H24/I24,"") -> 0.175 | K24: =IFERROR(J24/SUBTOTAL(9,$J$2:$J$1048576),"") -> 0.045499079 | L24: =I24*G24 -> 1.4680496 | M24: =F24/(1-(F24*(1+H24)-F24)/(F24*(1+H24))) -> 35.9948 | N24: =M24*E24 -> 3.9270327 | O24: =IFERROR(VLOOKUP(C24,'PBI Open Positions'!A:F,6,0),VLOOKUP(Positions!C24,'Stock Selection'!C:H,6,0)) -> 38.5 | P24: =IFERROR(O24*E24,G24) -> 4.20035 | Q24: =P24-G24 -> 0.530226 | R24: =F24/(1+I24-H24) -> 25.293233 | S24: =M24-F24 -> 2.3548 | T24: =0.5*(R24-F24) -> -4.1733835 | U24: =S24+T24 -> -1.8185835 | V24: =SUBTOTAL(4,$U$2:$U$10000)-U24 -> 31.348519 | W24: =IFERROR((SUBTOTAL(109,$V$2:$V$1048576)/V24)/SUBTOTAL(109,$V$2:$V$1048576),0) -> 0 | X24: =V24/MAX($V$2:$V$28) -> 0.18153517
A25: Consumer Cyclical | B25: Yum! Brands | C25: YUM | D25: =IF(ISERROR(VLOOKUP(C25,[1]Sheet1!$C:$C,1,0)),TODAY(),_xlfn.MINIFS([1]Sheet1!$F:$F,[1]Sheet1!$C:$C,C25)) -> 45645.901 | E25: =IFERROR(VLOOKUP(C25,'PBI Open Positions'!A:J,4,0),1E-32) -> 0.2482 | F25: =IFERROR(VLOOKUP(C25,'PBI Open Positions'!A:J,5,0),VLOOKUP(C25,'Stock Selection'!C:H,6,0)) -> 141.14 | G25: =E25*F25 -> 35.030948 | H25: 0.07 | I25: 0.1623 | J25: =IFERROR(H25/I25,"") -> 0.43130006 | K25: =IFERROR(J25/SUBTOTAL(9,$J$2:$J$1048576),"") -> 0.11213575 | L25: =I25*G25 -> 5.6855229 | M25: =F25/(1-(F25*(1+H25)-F25)/(F25*(1+H25))) -> 151.0198 | N25: =M25*E25 -> 37.483114 | O25: =IFERROR(VLOOKUP(C25,'PBI Open Positions'!A:F,6,0),VLOOKUP(Positions!C25,'Stock Selection'!C:H,6,0)) -> 142.63 | P25: =IFERROR(O25*E25,G25) -> 35.400766 | Q25: =P25-G25 -> 0.369818 | R25: =F25/(1+I25-H25) -> 129.21359 | S25: =M25-F25 -> 9.8798 | T25: =0.5*(R25-F25) -> -5.963207 | U25: =S25+T25 -> 3.916593 | V25: =SUBTOTAL(4,$U$2:$U$10000)-U25 -> 25.613343 | W25: =IFERROR((SUBTOTAL(109,$V$2:$V$1048576)/V25)/SUBTOTAL(109,$V$2:$V$1048576),0) -> 0 | X25: =V25/MAX($V$2:$V$28) -> 0.14832351
A26: Technology | B26: Apple2 | C26: AAPL | D26: =IF(ISERROR(VLOOKUP(C26,[1]Sheet1!$C:$C,1,0)),TODAY(),_xlfn.MINIFS([1]Sheet1!$F:$F,[1]Sheet1!$C:$C,C26)) -> 45582.74 | E26: =IFERROR(VLOOKUP(C26,'PBI Open Positions'!A:J,4,0),1E-32) -> 0.0001 | F26: =IFERROR(VLOOKUP(C26,'PBI Open Positions'!A:J,5,0),VLOOKUP(C26,'Stock Selection'!C:H,6,0)) -> 200 | G26: =E26*F26 -> 0.02 | H26: 0.15 | I26: 0.2271 | J26: =IFERROR(H26/I26,"") -> 0.66050198 | K26: =IFERROR(J26/SUBTOTAL(9,$J$2:$J$1048576),"") -> 0.17172704 | L26: =I26*G26 -> 0.004542 | M26: =F26/(1-(F26*(1+H26)-F26)/(F26*(1+H26))) -> 230 | N26: =M26*E26 -> 0.023 | O26: =IFERROR(VLOOKUP(C26,'PBI Open Positions'!A:F,6,0),VLOOKUP(Positions!C26,'Stock Selection'!C:H,6,0)) -> 200 | P26: =IFERROR(O26*E26,G26) -> 0.02 | Q26: =P26-G26 -> 0 | R26: =F26/(1+I26-H26) -> 185.68378 | S26: =M26-F26 -> 30 | T26: =0.5*(R26-F26) -> -7.1581097 | U26: =S26+T26 -> 22.84189 | V26: =SUBTOTAL(4,$U$2:$U$10000)-U26 -> 6.6880453 | W26: =IFERROR((SUBTOTAL(109,$V$2:$V$1048576)/V26)/SUBTOTAL(109,$V$2:$V$1048576),0) -> 0 | X26: =V26/MAX($V$2:$V$28) -> 0.038729595
A27: Energy & Utilities | B27: Excelon | C27: EXC | D27: =IF(ISERROR(VLOOKUP(C27,[1]Sheet1!$C:$C,1,0)),TODAY(),_xlfn.MINIFS([1]Sheet1!$F:$F,[1]Sheet1!$C:$C,C27)) -> 45708.68 | E27: =IFERROR(VLOOKUP(C27,'PBI Open Positions'!A:J,4,0),1E-32) -> 0.6951 | F27: =IFERROR(VLOOKUP(C27,'PBI Open Positions'!A:J,5,0),VLOOKUP(C27,'Stock Selection'!C:H,6,0)) -> 43.16 | G27: =E27*F27 -> 30.000516 | H27: 0.05 | I27: 0.2029 | J27: =IFERROR(H27/I27,"") -> 0.24642681 | K27: =IFERROR(J27/SUBTOTAL(9,$J$2:$J$1048576),"") -> 0.064069674 | L27: =I27*G27 -> 6.0871047 | M27: =F27/(1-(F27*(1+H27)-F27)/(F27*(1+H27))) -> 45.318 | N27: =M27*E27 -> 31.500542 | O27: =IFERROR(VLOOKUP(C27,'PBI Open Positions'!A:F,6,0),VLOOKUP(Positions!C27,'Stock Selection'!C:H,6,0)) -> 43.09 | P27: =IFERROR(O27*E27,G27) -> 29.951859 | Q27: =P27-G27 -> -0.048657 | R27: =F27/(1+I27-H27) -> 37.436031 | S27: =M27-F27 -> 2.158 | T27: =0.5*(R27-F27) -> -2.8619846 | U27: =S27+T27 -> -0.70398456 | V27: =SUBTOTAL(4,$U$2:$U$10000)-U27 -> 30.23392 | W27: =IFERROR((SUBTOTAL(109,$V$2:$V$1048576)/V27)/SUBTOTAL(109,$V$2:$V$1048576),0) -> 0 | X27: =V27/MAX($V$2:$V$28) -> 0.17508067
A28: FOREX | B28: Gold | C28: GC=F | D28: =IF(ISERROR(VLOOKUP(C28,[1]Sheet1!$C:$C,1,0)),TODAY(),_xlfn.MINIFS([1]Sheet1!$F:$F,[1]Sheet1!$C:$C,C28)) -> 45833 | E28: =IFERROR(VLOOKUP(C28,'PBI Open Positions'!A:J,4,0),1E-32) -> 1e-32 | F28: =IFERROR(VLOOKUP(C28,'PBI Open Positions'!A:J,5,0),VLOOKUP(C28,'Stock Selection'!C:H,6,0)) -> 3340.3 | G28: =E28*F28 -> 3.3403e-29 | H28: 0.1 | I28: 0.5 | J28: =IFERROR(H28/I28,"") -> 0.2 | K28: =IFERROR(J28/SUBTOTAL(9,$J$2:$J$1048576),"") -> 0.051998947 | L28: =I28*G28 -> 1.67015e-29 | M28: =F28/(1-(F28*(1+H28)-F28)/(F28*(1+H28))) -> 3674.33 | N28: =M28*E28 -> 3.67433e-29 | O28: =IFERROR(VLOOKUP(C28,'PBI Open Positions'!A:F,6,0),VLOOKUP(Positions!C28,'Stock Selection'!C:H,6,0)) -> 3340.3 | P28: =IFERROR(O28*E28,G28) -> 3.3403e-29 | Q28: =P28-G28 -> 0 | R28: =F28/(1+I28-H28) -> 2385.9286 | S28: =M28-F28 -> 334.03 | T28: =0.5*(R28-F28) -> -477.18571 | U28: =S28+T28 -> -143.15571 | V28: =SUBTOTAL(4,$U$2:$U$10000)-U28 -> 172.68565 | W28: =IFERROR((SUBTOTAL(109,$V$2:$V$1048576)/V28)/SUBTOTAL(109,$V$2:$V$1048576),0) -> 0 | X28: =V28/MAX($V$2:$V$28) -> 1
A29: Technology | B29: ASML | C29: ASML | D29: =IF(ISERROR(VLOOKUP(C29,[1]Sheet1!$C:$C,1,0)),TODAY(),_xlfn.MINIFS([1]Sheet1!$F:$F,[1]Sheet1!$C:$C,C29)) -> 45833 | E29: =IFERROR(VLOOKUP(C29,'PBI Open Positions'!A:J,4,0),1E-32) -> 1e-32 | F29: =IFERROR(VLOOKUP(C29,'PBI Open Positions'!A:J,5,0),VLOOKUP(C29,'Stock Selection'!C:H,6,0)) -> 813.36 | G29: =E29*F29 -> 8.1336e-30 | H29: 0.1 | I29: 0.4534 | J29: =IFERROR(H29/I29,"") -> 0.2205558 | K29: =IFERROR(J29/SUBTOTAL(9,$J$2:$J$1048576),"") -> 0.057343347 | L29: =I29*G29 -> 3.6877742e-30 | M29: =F29/(1-(F29*(1+H29)-F29)/(F29*(1+H29))) -> 894.696 | N29: =M29*E29 -> 8.94696e-30 | O29: =IFERROR(VLOOKUP(C29,'PBI Open Positions'!A:F,6,0),VLOOKUP(Positions!C29,'Stock Selection'!C:H,6,0)) -> 813.36 | P29: =IFERROR(O29*E29,G29) -> 8.1336e-30 | Q29: =P29-G29 -> 0 | R29: =F29/(1+I29-H29) -> 600.97532 | S29: =M29-F29 -> 81.336 | T29: =0.5*(R29-F29) -> -106.19234 | U29: =S29+T29 -> -24.856339 | V29: =SUBTOTAL(4,$U$2:$U$10000)-U29 -> 54.386275 | W29: =IFERROR((SUBTOTAL(109,$V$2:$V$1048576)/V29)/SUBTOTAL(109,$V$2:$V$1048576),0) -> 0 | X29: =V29/MAX($V$2:$V$28) -> 0.3149438
A30: Consumer Cyclical | B30: LVMH | C30: MC.PA | D30: =IF(ISERROR(VLOOKUP(C30,[1]Sheet1!$C:$C,1,0)),TODAY(),_xlfn.MINIFS([1]Sheet1!$F:$F,[1]Sheet1!$C:$C,C30)) -> 45833 | E30: =IFERROR(VLOOKUP(C30,'PBI Open Positions'!A:J,4,0),1E-32) -> 1e-32 | F30: =IFERROR(VLOOKUP(C30,'PBI Open Positions'!A:J,5,0),VLOOKUP(C30,'Stock Selection'!C:H,6,0)) -> 453.55 | G30: =E30*F30 -> 4.5355e-30 | H30: 0.05 | I30: 0.28 | J30: =IFERROR(H30/I30,"") -> 0.17857143 | K30: =IFERROR(J30/SUBTOTAL(9,$J$2:$J$1048576),"") -> 0.046427632 | L30: =I30*G30 -> 1.26994e-30 | M30: =F30/(1-(F30*(1+H30)-F30)/(F30*(1+H30))) -> 476.2275 | N30: =M30*E30 -> 4.762275e-30 | O30: =IFERROR(VLOOKUP(C30,'PBI Open Positions'!A:F,6,0),VLOOKUP(Positions!C30,'Stock Selection'!C:H,6,0)) -> 453.55 | P30: =IFERROR(O30*E30,G30) -> 4.5355e-30 | Q30: =P30-G30 -> 0 | R30: =F30/(1+I30-H30) -> 368.73984 | S30: =M30-F30 -> 22.6775 | T30: =0.5*(R30-F30) -> -42.405081 | U30: =S30+T30 -> -19.727581 | V30: =SUBTOTAL(4,$U$2:$U$10000)-U30 -> 49.257517 | W30: =IFERROR((SUBTOTAL(109,$V$2:$V$1048576)/V30)/SUBTOTAL(109,$V$2:$V$1048576),0) -> 0 | X30: =V30/MAX($V$2:$V$28) -> 0.28524383
A31: Healthcare | B31: HCA Healthcare | C31: HCA | D31: =IF(ISERROR(VLOOKUP(C31,[1]Sheet1!$C:$C,1,0)),TODAY(),_xlfn.MINIFS([1]Sheet1!$F:$F,[1]Sheet1!$C:$C,C31)) -> 45833 | E31: =IFERROR(VLOOKUP(C31,'PBI Open Positions'!A:J,4,0),1E-32) -> 1e-32 | F31: =IFERROR(VLOOKUP(C31,'PBI Open Positions'!A:J,5,0),VLOOKUP(C31,'Stock Selection'!C:H,6,0)) -> 379.02 | G31: =E31*F31 -> 3.7902e-30 | H31: 0.2 | I31: 0.2 | J31: =IFERROR(H31/I31,"") -> 1 | K31: =IFERROR(J31/SUBTOTAL(9,$J$2:$J$1048576),"") -> 0.25999474 | L31: =I31*G31 -> 7.5804e-31 | M31: =F31/(1-(F31*(1+H31)-F31)/(F31*(1+H31))) -> 454.824 | N31: =M31*E31 -> 4.54824e-30 | O31: =IFERROR(VLOOKUP(C31,'PBI Open Positions'!A:F,6,0),VLOOKUP(Positions!C31,'Stock Selection'!C:H,6,0)) -> 379.02 | P31: =IFERROR(O31*E31,G31) -> 3.7902e-30 | Q31: =P31-G31 -> 0 | R31: =F31/(1+I31-H31) -> 379.02 | S31: =M31-F31 -> 75.804 | T31: =0.5*(R31-F31) -> 0 | U31: =S31+T31 -> 75.804 | V31: =SUBTOTAL(4,$U$2:$U$10000)-U31 -> -46.274064 | W31: =IFERROR((SUBTOTAL(109,$V$2:$V$1048576)/V31)/SUBTOTAL(109,$V$2:$V$1048576),0) -> 0 | X31: =V31/MAX($V$2:$V$28) -> -0.26796705
A32: Technology | B32: QualComm2 | C32: QCOM | D32: =IF(ISERROR(VLOOKUP(C32,[1]Sheet1!$C:$C,1,0)),TODAY(),_xlfn.MINIFS([1]Sheet1!$F:$F,[1]Sheet1!$C:$C,C32)) -> 45833 | E32: =IFERROR(VLOOKUP(C32,'PBI Open Positions'!A:J,4,0),1E-32) -> 1e-32 | F32: =IFERROR(VLOOKUP(C32,'PBI Open Positions'!A:J,5,0),VLOOKUP(C32,'Stock Selection'!C:H,6,0)) -> 155.71 | G32: =E32*F32 -> 1.5571e-30 | H32: 0.15 | I32: 0.3778 | J32: =IFERROR(H32/I32,"") -> 0.39703547 | K32: =IFERROR(J32/SUBTOTAL(9,$J$2:$J$1048576),"") -> 0.10322713 | L32: =I32*G32 -> 5.8827238e-31 | M32: =F32/(1-(F32*(1+H32)-F32)/(F32*(1+H32))) -> 179.0665 | N32: =M32*E32 -> 1.790665e-30 | O32: =IFERROR(VLOOKUP(C32,'PBI Open Positions'!A:F,6,0),VLOOKUP(Positions!C32,'Stock Selection'!C:H,6,0)) -> 155.71 | P32: =IFERROR(O32*E32,G32) -> 1.5571e-30 | Q32: =P32-G32 -> 0 | R32: =F32/(1+I32-H32) -> 126.82033 | S32: =M32-F32 -> 23.3565 | T32: =0.5*(R32-F32) -> -14.444835 | U32: =S32+T32 -> 8.9116645 | V32: =SUBTOTAL(4,$U$2:$U$10000)-U32 -> 20.618271 | W32: =IFERROR((SUBTOTAL(109,$V$2:$V$1048576)/V32)/SUBTOTAL(109,$V$2:$V$1048576),0) -> 0 | X32: =V32/MAX($V$2:$V$28) -> 0.11939771
... A36: Industrials | B36: 3M | C36: MMM | D36: =IF(ISERROR(VLOOKUP(C36,[1]Sheet1!$C:$C,1,0)),TODAY(),_xlfn.MINIFS([1]Sheet1!$F:$F,[1]Sheet1!$C:$C,C36)) -> 45833 | E36: =IFERROR(VLOOKUP(C36,'PBI Open Positions'!A:J,4,0),1E-32) -> 1e-32 | F36: =IFERROR(VLOOKUP(C36,'PBI Open Positions'!A:J,5,0),VLOOKUP(C36,'Stock Selection'!C:H,6,0)) -> 149.87 | G36: =E36*F36 -> 1.4987e-30 | H36: 0.07 | I36: 0.2 | J36: =IFERROR(H36/I36,"") -> 0.35 | K36: =IFERROR(J36/SUBTOTAL(9,$J$2:$J$1048576),"") -> 0.090998158 | L36: =I36*G36 -> 2.9974e-31 | M36: =F36/(1-(F36*(1+H36)-F36)/(F36*(1+H36))) -> 160.3609 | N36: =M36*E36 -> 1.603609e-30 | O36: =IFERROR(VLOOKUP(C36,'PBI Open Positions'!A:F,6,0),VLOOKUP(Positions!C36,'Stock Selection'!C:H,6,0)) -> 149.87 | P36: =IFERROR(O36*E36,G36) -> 1.4987e-30 | Q36: =P36-G36 -> 0 | R36: =F36/(1+I36-H36) -> 132.62832 | S36: =M36-F36 -> 10.4909 | T36: =0.5*(R36-F36) -> -8.6208407 | U36: =S36+T36 -> 1.8700593 | V36: =SUBTOTAL(4,$U$2:$U$10000)-U36 -> 27.659876 | W36: =IFERROR((SUBTOTAL(109,$V$2:$V$1048576)/V36)/SUBTOTAL(109,$V$2:$V$1048576),0) -> 0 | X36: =V36/MAX($V$2:$V$28) -> 0.16017472
A37: Energy & Utilities | B37: Duke Energy | C37: DUK | D37: =IF(ISERROR(VLOOKUP(C37,[1]Sheet1!$C:$C,1,0)),TODAY(),_xlfn.MINIFS([1]Sheet1!$F:$F,[1]Sheet1!$C:$C,C37)) -> 45833 | E37: =IFERROR(VLOOKUP(C37,'PBI Open Positions'!A:J,4,0),1E-32) -> 1e-32 | F37: =IFERROR(VLOOKUP(C37,'PBI Open Positions'!A:J,5,0),VLOOKUP(C37,'Stock Selection'!C:H,6,0)) -> 116.95 | G37: =E37*F37 -> 1.1695e-30 | H37: =121.15/F37-1 -> 0.035912783 | I37: 0.1768 | J37: =IFERROR(H37/I37,"") -> 0.2031266 | K37: =IFERROR(J37/SUBTOTAL(9,$J$2:$J$1048576),"") -> 0.052811847 | L37: =I37*G37 -> 2.067676e-31 | M37: =F37/(1-(F37*(1+H37)-F37)/(F37*(1+H37))) -> 121.15 | N37: =M37*E37 -> 1.2115e-30 | O37: =IFERROR(VLOOKUP(C37,'PBI Open Positions'!A:F,6,0),VLOOKUP(Positions!C37,'Stock Selection'!C:H,6,0)) -> 116.95 | P37: =IFERROR(O37*E37,G37) -> 1.1695e-30 | Q37: =P37-G37 -> 0 | R37: =F37/(1+I37-H37) -> 102.50794 | S37: =M37-F37 -> 4.2 | T37: =0.5*(R37-F37) -> -7.2210293 | U37: =S37+T37 -> -3.0210293 | V37: =SUBTOTAL(4,$U$2:$U$10000)-U37 -> 32.550965 | W37: =IFERROR((SUBTOTAL(109,$V$2:$V$1048576)/V37)/SUBTOTAL(109,$V$2:$V$1048576),0) -> 0 | X37: =V37/MAX($V$2:$V$28) -> 0.18849838
A38: Consumer Defensive | B38: Walmart | C38: WMT | D38: =IF(ISERROR(VLOOKUP(C38,[1]Sheet1!$C:$C,1,0)),TODAY(),_xlfn.MINIFS([1]Sheet1!$F:$F,[1]Sheet1!$C:$C,C38)) -> 45833 | E38: =IFERROR(VLOOKUP(C38,'PBI Open Positions'!A:J,4,0),1E-32) -> 1e-32 | F38: =IFERROR(VLOOKUP(C38,'PBI Open Positions'!A:J,5,0),VLOOKUP(C38,'Stock Selection'!C:H,6,0)) -> 98 | G38: =E38*F38 -> 9.8e-31 | H38: 0.07 | I38: 0.1725 | J38: =IFERROR(H38/I38,"") -> 0.4057971 | K38: =IFERROR(J38/SUBTOTAL(9,$J$2:$J$1048576),"") -> 0.10550511 | L38: =I38*G38 -> 1.6905e-31 | M38: =F38/(1-(F38*(1+H38)-F38)/(F38*(1+H38))) -> 104.86 | N38: =M38*E38 -> 1.0486e-30 | O38: =IFERROR(VLOOKUP(C38,'PBI Open Positions'!A:F,6,0),VLOOKUP(Positions!C38,'Stock Selection'!C:H,6,0)) -> 98 | P38: =IFERROR(O38*E38,G38) -> 9.8e-31 | Q38: =P38-G38 -> 0 | R38: =F38/(1+I38-H38) -> 88.888889 | S38: =M38-F38 -> 6.86 | T38: =0.5*(R38-F38) -> -4.5555556 | U38: =S38+T38 -> 2.3044444 | V38: =SUBTOTAL(4,$U$2:$U$10000)-U38 -> 27.225491 | W38: =IFERROR((SUBTOTAL(109,$V$2:$V$1048576)/V38)/SUBTOTAL(109,$V$2:$V$1048576),0) -> 0 | X38: =V38/MAX($V$2:$V$28) -> 0.15765926
A39: Technology | B39: Palantir | C39: PLTR | D39: =IF(ISERROR(VLOOKUP(C39,[1]Sheet1!$C:$C,1,0)),TODAY(),_xlfn.MINIFS([1]Sheet1!$F:$F,[1]Sheet1!$C:$C,C39)) -> 45833 | E39: =IFERROR(VLOOKUP(C39,'PBI Open Positions'!A:J,4,0),1E-32) -> 1e-32 | F39: =IFERROR(VLOOKUP(C39,'PBI Open Positions'!A:J,5,0),VLOOKUP(C39,'Stock Selection'!C:H,6,0)) -> 143.23 | G39: =E39*F39 -> 1.4323e-30 | H39: 0.15 | I39: 0.673 | J39: =IFERROR(H39/I39,"") -> 0.22288262 | K39: =IFERROR(J39/SUBTOTAL(9,$J$2:$J$1048576),"") -> 0.057948307 | L39: =I39*G39 -> 9.639379e-31 | M39: =F39/(1-(F39*(1+H39)-F39)/(F39*(1+H39))) -> 164.7145 | N39: =M39*E39 -> 1.647145e-30 | O39: =IFERROR(VLOOKUP(C39,'PBI Open Positions'!A:F,6,0),VLOOKUP(Positions!C39,'Stock Selection'!C:H,6,0)) -> 143.23 | P39: =IFERROR(O39*E39,G39) -> 1.4323e-30 | Q39: =P39-G39 -> 0 | R39: =F39/(1+I39-H39) -> 94.044649 | S39: =M39-F39 -> 21.4845 | T39: =0.5*(R39-F39) -> -24.592676 | U39: =S39+T39 -> -3.1081756 | V39: =SUBTOTAL(4,$U$2:$U$10000)-U39 -> 32.638111 | W39: =IFERROR((SUBTOTAL(109,$V$2:$V$1048576)/V39)/SUBTOTAL(109,$V$2:$V$1048576),0) -> 0 | X39: =V39/MAX($V$2:$V$28) -> 0.18900303
A40: Consumer Cyclical | B40: Aptive Autoparts | C40: APTV | D40: =IF(ISERROR(VLOOKUP(C40,[1]Sheet1!$C:$C,1,0)),TODAY(),_xlfn.MINIFS([1]Sheet1!$F:$F,[1]Sheet1!$C:$C,C40)) -> 45833 | E40: =IFERROR(VLOOKUP(C40,'PBI Open Positions'!A:J,4,0),1E-32) -> 1e-32 | F40: =IFERROR(VLOOKUP(C40,'PBI Open Positions'!A:J,5,0),VLOOKUP(C40,'Stock Selection'!C:H,6,0)) -> 68.45 | G40: =E40*F40 -> 6.845e-31 | H40: 0.07 | I40: 0.19 | J40: =IFERROR(H40/I40,"") -> 0.36842105 | K40: =IFERROR(J40/SUBTOTAL(9,$J$2:$J$1048576),"") -> 0.095787535 | L40: =I40*G40 -> 1.30055e-31 | M40: =F40/(1-(F40*(1+H40)-F40)/(F40*(1+H40))) -> 73.2415 | N40: =M40*E40 -> 7.32415e-31 | O40: =IFERROR(VLOOKUP(C40,'PBI Open Positions'!A:F,6,0),VLOOKUP(Positions!C40,'Stock Selection'!C:H,6,0)) -> 68.45 | P40: =IFERROR(O40*E40,G40) -> 6.845e-31 | Q40: =P40-G40 -> 0 | R40: =F40/(1+I40-H40) -> 61.116071 | S40: =M40-F40 -> 4.7915 | T40: =0.5*(R40-F40) -> -3.6669643 | U40: =S40+T40 -> 1.1245357 | V40: =SUBTOTAL(4,$U$2:$U$10000)-U40 -> 28.4054 | W40: =IFERROR((SUBTOTAL(109,$V$2:$V$1048576)/V40)/SUBTOTAL(109,$V$2:$V$1048576),0) -> 0 | X40: =V40/MAX($V$2:$V$28) -> 0.16449195
A41: Consumer Cyclical | B41: Yum China Holding | C41: YUMC | D41: =IF(ISERROR(VLOOKUP(C41,[1]Sheet1!$C:$C,1,0)),TODAY(),_xlfn.MINIFS([1]Sheet1!$F:$F,[1]Sheet1!$C:$C,C41)) -> 45833 | E41: =IFERROR(VLOOKUP(C41,'PBI Open Positions'!A:J,4,0),1E-32) -> 1e-32 | F41: =IFERROR(VLOOKUP(C41,'PBI Open Positions'!A:J,5,0),VLOOKUP(C41,'Stock Selection'!C:H,6,0)) -> 44.4 | G41: =E41*F41 -> 4.44e-31 | H41: 0.07 | I41: 0.4 | J41: =IFERROR(H41/I41,"") -> 0.175 | K41: =IFERROR(J41/SUBTOTAL(9,$J$2:$J$1048576),"") -> 0.045499079 | L41: =I41*G41 -> 1.776e-31 | M41: =F41/(1-(F41*(1+H41)-F41)/(F41*(1+H41))) -> 47.508 | N41: =M41*E41 -> 4.7508e-31 | O41: =IFERROR(VLOOKUP(C41,'PBI Open Positions'!A:F,6,0),VLOOKUP(Positions!C41,'Stock Selection'!C:H,6,0)) -> 44.4 | P41: =IFERROR(O41*E41,G41) -> 4.44e-31 | Q41: =P41-G41 -> 0 | R41: =F41/(1+I41-H41) -> 33.383459 | S41: =M41-F41 -> 3.108 | T41: =0.5*(R41-F41) -> -5.5082707 | U41: =S41+T41 -> -2.4002707 | V41: =SUBTOTAL(4,$U$2:$U$10000)-U41 -> 31.930206 | W41: =IFERROR((SUBTOTAL(109,$V$2:$V$1048576)/V41)/SUBTOTAL(109,$V$2:$V$1048576),0) -> 0 | X41: =V41/MAX($V$2:$V$28) -> 0.18490365
A42: Energy & Utilities | B42: PG&E | C42: PCG | D42: =IF(ISERROR(VLOOKUP(C42,[1]Sheet1!$C:$C,1,0)),TODAY(),_xlfn.MINIFS([1]Sheet1!$F:$F,[1]Sheet1!$C:$C,C42)) -> 45833 | E42: =IFERROR(VLOOKUP(C42,'PBI Open Positions'!A:J,4,0),1E-32) -> 1e-32 | F42: =IFERROR(VLOOKUP(C42,'PBI Open Positions'!A:J,5,0),VLOOKUP(C42,'Stock Selection'!C:H,6,0)) -> 14.16 | G42: =E42*F42 -> 1.416e-31 | H42: 0.1 | I42: 0.2255 | J42: =IFERROR(H42/I42,"") -> 0.44345898 | K42: =IFERROR(J42/SUBTOTAL(9,$J$2:$J$1048576),"") -> 0.115297 | L42: =I42*G42 -> 3.19308e-32 | M42: =F42/(1-(F42*(1+H42)-F42)/(F42*(1+H42))) -> 15.576 | N42: =M42*E42 -> 1.5576e-31 | O42: =IFERROR(VLOOKUP(C42,'PBI Open Positions'!A:F,6,0),VLOOKUP(Positions!C42,'Stock Selection'!C:H,6,0)) -> 14.16 | P42: =IFERROR(O42*E42,G42) -> 1.416e-31 | Q42: =P42-G42 -> 0 | R42: =F42/(1+I42-H42) -> 12.581075 | S42: =M42-F42 -> 1.416 | T42: =0.5*(R42-F42) -> -0.78946246 | U42: =S42+T42 -> 0.62653754 | V42: =SUBTOTAL(4,$U$2:$U$10000)-U42 -> 28.903398 | W42: =IFERROR((SUBTOTAL(109,$V$2:$V$1048576)/V42)/SUBTOTAL(109,$V$2:$V$1048576),0) -> 0 | X42: =V42/MAX($V$2:$V$28) -> 0.1673758
A43: Technology | B43: Jinko Solar | C43: JKS | D43: =IF(ISERROR(VLOOKUP(C43,[1]Sheet1!$C:$C,1,0)),TODAY(),_xlfn.MINIFS([1]Sheet1!$F:$F,[1]Sheet1!$C:$C,C43)) -> 45833 | E43: =IFERROR(VLOOKUP(C43,'PBI Open Positions'!A:J,4,0),1E-32) -> 1e-32 | F43: =IFERROR(VLOOKUP(C43,'PBI Open Positions'!A:J,5,0),VLOOKUP(C43,'Stock Selection'!C:H,6,0)) -> 20.44 | G43: =E43*F43 -> 2.044e-31 | H43: 0.05 | I43: 0.6681 | J43: =IFERROR(H43/I43,"") -> 0.074839096 | K43: =IFERROR(J43/SUBTOTAL(9,$J$2:$J$1048576),"") -> 0.019457771 | L43: =I43*G43 -> 1.3655964e-31 | M43: =F43/(1-(F43*(1+H43)-F43)/(F43*(1+H43))) -> 21.462 | N43: =M43*E43 -> 2.1462e-31 | O43: =IFERROR(VLOOKUP(C43,'PBI Open Positions'!A:F,6,0),VLOOKUP(Positions!C43,'Stock Selection'!C:H,6,0)) -> 20.44 | P43: =IFERROR(O43*E43,G43) -> 2.044e-31 | Q43: =P43-G43 -> 0 | R43: =F43/(1+I43-H43) -> 12.632099 | S43: =M43-F43 -> 1.022 | T43: =0.5*(R43-F43) -> -3.9039503 | U43: =S43+T43 -> -2.8819503 | V43: =SUBTOTAL(4,$U$2:$U$10000)-U43 -> 32.411886 | W43: =IFERROR((SUBTOTAL(109,$V$2:$V$1048576)/V43)/SUBTOTAL(109,$V$2:$V$1048576),0) -> 0 | X43: =V43/MAX($V$2:$V$28) -> 0.18769299
...

Sheet PBI Open Positions
A1: Ticker | B1: Entry Value | C1: Entry % | D1: Volume | E1: Open Price | F1: Market Price | G1: Market Value | H1: Unrealized Gains | I1: Gains % | J1: Volatility
A2: VWO | B2: 182.42 | C2: 0.1 | D2: 4 | E2: 45.61 | F2: 49.01 | G2: 196.04 | H2: 13.62 | I2: 0.0747 | J2: 0.19
A3: BND | B3: 147 | C3: 0.08 | D3: 2 | E3: 73.5 | F3: 73.28 | G3: 146.56 | H3: -0.44 | I3: -0.003 | J3: 0.05
A4: APA | B4: 129.96 | C4: 0.07 | D4: 6.8599 | E4: 18.94 | F4: 18.17 | G4: 124.64 | H4: -5.32 | I4: -0.0409 | J4: 0.52
A5: MO | B5: 129.74 | C5: 0.07 | D5: 2.3939 | E5: 54.2 | F5: 59.93 | G5: 143.46 | H5: 13.72 | I5: 0.1057 | J5: 0.19
A6: ACI | B6: 126.28 | C6: 0.07 | D6: 6 | E6: 21.05 | F6: 21.68 | G6: 130.08 | H6: 3.8 | I6: 0.0301 | J6: 0.25
A7: PEP | B7: 119 | C7: 0.07 | D7: 0.8085 | E7: 147.19 | F7: 131.08 | G7: 105.98 | H7: -13.02 | I7: -0.1094 | J7: 0.2
A8: BBVA.MC | B8: 89.99 | C8: 0.05 | D8: 6.0332 | E8: 14.92 | F8: 15.14 | G8: 91.33 | H8: 1.34 | I8: 0.0149 | J8: 0.3
A9: YPF | B9: 89.97 | C9: 0.05 | D9: 2.4948 | E9: 36.06 | F9: 34.37 | G9: 85.74 | H9: -4.23 | I9: -0.047 | J9: 0.48
A10: TSM | B10: 89.04 | C10: 0.05 | D10: 0.5547 | E10: 160.52 | F10: 220.05 | G10: 122.06 | H10: 33.02 | I10: 0.3708 | J10: 0.46
A11: ING | B11: 85.63 | C11: 0.05 | D11: 4.8753 | E11: 17.56 | F11: 21.35 | G11: 104.08 | H11: 18.45 | I11: 0.2155 | J11: 0.27
A12: BCS | B12: 80 | C12: 0.04 | D12: 4.8087 | E12: 16.64 | F12: 18.25 | G12: 87.76 | H12: 7.76 | I12: 0.097 | J12: 0.36
A13: NEE | B13: 69.98 | C13: 0.04 | D13: 0.9669 | E13: 72.38 | F13: 71.42 | G13: 69.06 | H13: -0.92 | I13: -0.0131 | J13: 0.29
... A27: DAR | B27: 3.67 | C27: 0 | D27: 0.1091 | E27: 33.64 | F27: 38.5 | G27: 4.2 | H27: 0.53 | I27: 0.1444 | J27: 0.45
A28: AGIO | B28: 0.55 | C28: 0 | D28: 0.0179 | E28: 30.73 | F28: 33.52 | G28: 0.6 | H28: 0.05 | I28: 0.0909 | J28: (Blank)
A29: MSFT | B29: 0.41 | C29: 0 | D29: 0.001 | E29: 410 | F29: 490 | G29: 0.49 | H29: 0.08 | I29: 0.1951 | J29: 0.26
A30: AAPL | B30: 0.02 | C30: 0 | D30: 0.0001 | E30: 200 | F30: 200 | G30: 0.02 | H30: 0 | I30: 0 | J30: 0.32

Sheet Stock Selection
A1: Sector | B1: GICS Sector | C1: Ticker | D1: Portfolio % | E1: Net Income % | F1: EBITDA Margin % | G1: Dividend | H1: Close Price | I1: EPS | J1: Forward EPS | K1: EPG Growth % | L1: PEG | M1: P/E | N1: Forward P/E | O1: Volatility | P1: MISSING
A2: Financial Services | B2: Financial Services | C2: V | D2: 0.0115 | E2: 52.210203 | F2: 69.708 | G2: 0.0069 | H2: 351.63 | I2: 9.93 | J2: 12.66 | K2: 0.2749 | L2: 1.0102731 | M2: 35.410877 | N2: 27.774881 | O2: 0.2326 | P2: =NOT(VLOOKUP(C2,Positions!C:C,1,0)=C2) -> FALSE
A3: Technology | B3: Technology | C3: NVDA | E3: 51.694442 | F3: 59.419996 | G3: 0.0003 | H3: 147.9 | I3: 3.1 | J3: 4.12 | K3: 0.329 | L3: 1.0910193 | M3: 47.70968 | N3: 35.898056 | O3: 0.5757 | P3: =NOT(VLOOKUP(C3,Positions!C:C,1,0)=C3) -> FALSE
A4: Consumer Def & Cyclical | B4: Consumer Defensive | C4: MO | D4: 0.0752 | E4: 50.301293 | F4: 61.162996 | G4: 0.0674 | H4: 59.91 | I4: 5.96 | J4: 5.35 | K4: -0.1023 | L4: -1.0941125 | M4: 10.052013 | N4: 11.198131 | O4: 0.1949 | P4: =NOT(VLOOKUP(C4,Positions!C:C,1,0)=C4) -> FALSE
A5: Financial Services | B5: Financial Services | C5: MA | D5: 0.0228 | E5: 45.213113 | F5: 61.846 | G5: 0.0056 | H5: 557.53 | I5: 14.26 | J5: 16.38 | K5: 0.1487 | L5: 2.2894863 | M5: 39.097477 | N5: 34.037243 | O5: 0.2277 | P5: =NOT(VLOOKUP(C5,Positions!C:C,1,0)=C5) -> FALSE
A6: Technology | B6: Technology | C6: TSM | D6: 0.064 | E6: 41.68677 | F6: 68.481004 | G6: 0.0156 | H6: 220.09 | I6: 8.43 | J6: 8.08 | K6: -0.0415 | L6: -6.5606742 | M6: 26.107946 | N6: 27.238861 | O6: 0.4588 | P6: =NOT(VLOOKUP(C6,Positions!C:C,1,0)=C6) -> FALSE
A7: Technology | B7: Technology | C7: MSFT | D7: 0.0003 | E7: 35.789415 | F7: 55.247 | G7: 0.0068 | H7: 490.11 | I7: 12.93 | J7: 14.95 | K7: 0.1562 | L7: 2.0984543 | M7: 37.90487 | N7: 32.783276 | O7: 0.2559 | P7: =NOT(VLOOKUP(C7,Positions!C:C,1,0)=C7) -> FALSE
A8: Financial Services | B8: Financial Services | C8: BBVA.MC | D8: 0.0479 | E8: 31.698101 | F8: 0 | G8: 0.0547 | H8: 13.11 | I8: 1.77 | J8: 0.94 | K8: -0.4689 | L8: -0.29753331 | M8: 7.4096045 | N8: 13.952127 | O8: 0.3012 | P8: =NOT(VLOOKUP(C8,Positions!C:C,1,0)=C8) -> FALSE
A9: Technology | B9: Communication Services | C9: GOOGL | D9: 0.0025 | E9: 30.85682 | F9: 37.726003 | G9: 0.0051 | H9: 166.77 | I9: 8.95 | J9: 8.96 | K9: 0.0011 | L9: 166.58388 | M9: 18.63352 | N9: 18.612724 | O9: 0.3187 | P9: =NOT(VLOOKUP(C9,Positions!C:C,1,0)=C9) -> FALSE
A10: Financial Services | B10: Financial Services | C10: BAP | D10: 0.0105 | E10: 30.761927 | F10: 0 | G10: 0.0509 | H10: 217.79 | I10: 19.8 | J10: 20.68 | K10: 0.0444 | L10: 2.369572 | M10: 10.999496 | N10: 10.531431 | O10: 0.2499 | P10: =NOT(VLOOKUP(C10,Positions!C:C,1,0)=C10) -> FALSE
A11: Energy & Utilities | B11: Technology | C11: FSLR | D11: 0.0392 | E11: 29.716644 | F11: 43.032002 | G11: 0 | H11: 151.18 | I11: 11.78 | J11: 20.86 | K11: 0.7708 | L11: 0.094024154 | M11: 12.833616 | N11: 7.2473626 | O11: 0.6306 | P11: =NOT(VLOOKUP(C11,Positions!C:C,1,0)=C11) -> FALSE
A12: Technology | B12: Technology | C12: ASML | E12: 28.334591 | F12: 36.578 | G12: 0.0107 | H12: 813.36 | I12: 25.5 | J12: 26.7 | K12: 0.0471 | L12: 6.4733705 | M12: 31.89647 | N12: 30.46292 | O12: 0.4773 | P12: =NOT(VLOOKUP(C12,Positions!C:C,1,0)=C12) -> FALSE
A13: Financial Services | B13: Financial Services | C13: CIB | D13: 0.0363 | E13: 28.104146 | F13: 0 | G13: 0.3578 | H13: 44.97 | I13: 6.45 | J13: 5.9 | K13: -0.0853 | L13: -0.89385671 | M13: 6.9720936 | N13: 7.622034 | O13: 0.3186 | P13: =NOT(VLOOKUP(C13,Positions!C:C,1,0)=C13) -> FALSE
A14: Technology | B14: Technology | C14: QCOM | E14: 26.048812 | F14: 31.573 | G14: 0.0232 | H14: 155.71 | I14: 9.8 | J14: 12.23 | K14: 0.248 | L14: 0.51346386 | M14: 15.888776 | N14: 12.731808 | O14: 0.4285 | P14: =NOT(VLOOKUP(C14,Positions!C:C,1,0)=C14) -> FALSE
A15: Financial Services | B15: Financial Services | C15: ING | D15: 0.0545 | E15: 25.98484 | F15: 0 | G15: 0.0554 | H15: 21.36 | I15: 2.27 | J15: 2.19 | K15: -0.0352 | L15: -2.7675343 | M15: 9.409692 | N15: 9.753425 | O15: 0.2737 | P15: =NOT(VLOOKUP(C15,Positions!C:C,1,0)=C15) -> FALSE
A16: Technology | B16: Technology | C16: AAPL | D16: 0 | E16: 24.301264 | F16: 34.685 | G16: 0.0052 | H16: 200.3 | I16: 6.43 | J16: 8.31 | K16: 0.2924 | L16: 0.82439061 | M16: 31.150856 | N16: 24.103489 | O16: 0.3232 | P16: =NOT(VLOOKUP(C16,Positions!C:C,1,0)=C16) -> FALSE
A17: Technology | B17: Technology | C17: AMAT | E17: 24.059241 | F17: 31.133 | G17: 0.0107 | H17: 180.18 | I17: 8.22 | J17: 9.69 | K17: 0.1788 | L17: 1.03977 | M17: 21.919706 | N17: 18.594427 | O17: 0.4882 | P17: =NOT(VLOOKUP(C17,Positions!C:C,1,0)=C17) -> FALSE
A18: Financial Services | B18: Financial Services | C18: BCS | D18: 0.046 | E18: 22.632257 | F18: 0 | G18: 0.024 | H18: 18.26 | I18: 2.02 | J18: 1.05 | K18: -0.4802 | L18: -0.36215222 | M18: 9.039604 | N18: 17.390478 | O18: 0.3595 | P18: =NOT(VLOOKUP(C18,Positions!C:C,1,0)=C18) -> FALSE
A19: Financial Services | B19: Financial Services | C19: SMFG | E19: 22.567763 | F19: 0 | G19: 0.0277 | H19: 15.17 | I19: 1.24 | J19: 0.41 | K19: -0.6694 | L19: -0.55277108 | M19: 12.233871 | N19: 37 | O19: 0.364 | P19: =NOT(VLOOKUP(C19,Positions!C:C,1,0)=C19) -> FALSE
A20: Energy & Utilities | B20: Utilities | C20: NEE | D20: 0.0362 | E20: 21.809332 | F20: 53.73 | G20: 0.032 | H20: 71.4 | I20: 2.67 | J20: 3.68 | K20: 0.3783 | L20: 0.51290896 | M20: 26.741573 | N20: 19.402174 | O20: 0.2894 | P20: =NOT(VLOOKUP(C20,Positions!C:C,1,0)=C20) -> FALSE
A21: Healthcare | B21: Healthcare | C21: GILD | E21: 20.758657 | F21: 47.761002 | G21: 0.0298 | H21: 107.2 | I21: 4.76 | J21: 7.43 | K21: 0.5609 | L21: 0.25721819 | M21: 22.521008 | N21: 14.427995 | O21: 0.2606 | P21: =NOT(VLOOKUP(C21,Positions!C:C,1,0)=C21) -> FALSE
A22: Consumer Def & Cyclical | B22: Consumer Cyclical | C22: YUM | D22: 0.0185 | E22: 18.415611 | F22: 35.5 | G22: 0.0201 | H22: 142.7 | I22: 5.02 | J22: 6.08 | K22: 0.2112 | L22: 1.1115224 | M22: 28.426294 | N22: 23.470394 | O22: 0.2203 | P22: =NOT(VLOOKUP(C22,Positions!C:C,1,0)=C22) -> FALSE
A23: Technology | B23: Technology | C23: PLTR | E23: 18.320598 | F23: 13.976 | G23: 0 | H23: 143.23 | I23: 0.22 | J23: 0.47 | K23: 1.1364 | L23: 2.681753 | M23: 651.0454 | N23: 304.74466 | O23: 0.728 | P23: =NOT(VLOOKUP(C23,Positions!C:C,1,0)=C23) -> FALSE
A24: Industrials | B24: Industrials | C24: MMM | E24: 18.031248 | F24: 21.735 | G24: 0.0198 | H24: 149.87 | I24: 8.03 | J24: 7.9 | K24: -0.0162 | L24: -11.718169 | M24: 18.663761 | N24: 18.970884 | O24: 0.3632 | P24: =NOT(VLOOKUP(C24,Positions!C:C,1,0)=C24) -> FALSE
A25: Financial Services | B25: Financial Services | C25: C | D25: 0.0055 | E25: 16.937021 | F25: 0 | G25: 0.0282 | H25: 81.14 | I25: 6.33 | J25: 7.19 | K25: 0.1359 | L25: 0.83063717 | M25: 12.818325 | N25: 11.285118 | O25: 0.3434 | P25: =NOT(VLOOKUP(C25,Positions!C:C,1,0)=C25) -> FALSE
A26: Energy & Utilities | B26: Utilities | C26: DUK | E26: 15.22024 | F26: 48.826998 | G26: 0.0357 | H26: 116.95 | I26: 6.02 | J26: 6.34 | K26: 0.0532 | L26: 3.4702235 | M26: 19.42691 | N26: 18.446371 | O26: 0.1822 | P26: =NOT(VLOOKUP(C26,Positions!C:C,1,0)=C26) -> FALSE
A27: Consumer Def & Cyclical | B27: Consumer Cyclical | C27: MC.PA | E27: 14.819976 | F27: 26.488 | G27: 0.0289 | H27: 453.55 | I27: 25.1 | J27: 29.09 | K27: 0.159 | L27: 0.98080408 | M27: 18.069721 | N27: 15.591268 | O27: 0.3176 | P27: =NOT(VLOOKUP(C27,Positions!C:C,1,0)=C27) -> FALSE
A28: Energy & Utilities | B28: Utilities | C28: AEP | E28: 13.711989 | F28: 39.543 | G28: 0.036 | H28: 103.28 | I28: 5.18 | J28: 5.89 | K28: 0.1371 | L28: 1.2792999 | M28: 19.938225 | N28: 17.534805 | O28: 0.1947 | P28: =NOT(VLOOKUP(C28,Positions!C:C,1,0)=C28) -> FALSE
A29: Basic Materials | B29: Basic Materials | C29: SQM | E29: 13.449988 | F29: 29.632 | G29: 0.0613 | H29: 33.95 | I29: 2.11 | J29: 3.98 | K29: 0.8863 | L29: 0.096249297 | M29: 16.090048 | N29: 8.530151 | O29: 0.438 | P29: =NOT(VLOOKUP(C29,Positions!C:C,1,0)=C29) -> FALSE
A30: Consumer Def & Cyclical | B30: Consumer Defensive | C30: KMB | D30: 0.0325 | E30: 12.481645 | F30: 19.545001 | G30: 0.0387 | H30: 129.95 | I30: 7.34 | J30: 7.63 | K30: 0.0395 | L30: 4.3107197 | M30: 17.70436 | N30: 17.031454 | O30: 0.1946 | P30: =NOT(VLOOKUP(C30,Positions!C:C,1,0)=C30) -> FALSE
A31: Energy & Utilities | B31: Utilities | C31: EXC | D31: 0.0157 | E31: 11.435083 | F31: 32.266998 | G31: 0.037 | H31: 43.1 | I31: 2.69 | J31: 2.63 | K31: -0.0223 | L31: -7.3472104 | M31: 16.022305 | N31: 16.38783 | O31: 0.1918 | P31: =NOT(VLOOKUP(C31,Positions!C:C,1,0)=C31) -> FALSE
A32: Consumer Def & Cyclical | B32: Consumer Defensive | C32: PEP | D32: 0.0555 | E32: 10.237864 | F32: 18.906 | G32: 0.0441 | H32: 131.05 | I32: 6.8 | J32: 8.63 | K32: 0.2691 | L32: 0.56426623 | M32: 19.272058 | N32: 15.1854 | O32: 0.1956 | P32: =NOT(VLOOKUP(C32,Positions!C:C,1,0)=C32) -> FALSE
A33: Energy & Utilities | B33: Energy | C33: APA | D33: 0.0653 | E33: 10.041388 | F33: 58.8 | G33: 0.0544 | H33: 18.18 | I33: 2.79 | J33: 2.75 | K33: -0.0143 | L33: -4.611109 | M33: 6.516129 | N33: 6.610909 | O33: 0.5247 | P33: =NOT(VLOOKUP(C33,Positions!C:C,1,0)=C33) -> FALSE
A34: Energy & Utilities | B34: Utilities | C34: PCG | E34: 9.5758126 | F34: 38.176998 | G34: 0.0072 | H34: 14.16 | I34: 1.09 | J34: 1.48 | K34: 0.3578 | L34: 0.26740123 | M34: 12.990825 | N34: 9.567567 | O34: 0.2806 | P34: =NOT(VLOOKUP(C34,Positions!C:C,1,0)=C34) -> FALSE
A35: Consumer Def & Cyclical | B35: Consumer Defensive | C35: INGR | D35: 0.0251 | E35: 8.5314496 | F35: 17.511 | G35: 0.023 | H35: 137.5 | I35: 9.48 | J35: 11.11 | K35: 0.1719 | L35: 0.71979593 | M35: 14.50422 | N35: 12.376238 | O35: 0.2578 | P35: =NOT(VLOOKUP(C35,Positions!C:C,1,0)=C35) -> FALSE
A36: Consumer Def & Cyclical | B36: Consumer Cyclical | C36: YUMC | E36: 8.087586 | F36: 15.001 | G36: 0.0218 | H36: 44.4 | I36: 2.39 | J36: 2.58 | K36: 0.0795 | L36: 2.1647492 | M36: 18.577406 | N36: 17.209303 | O36: 0.4189 | P36: =NOT(VLOOKUP(C36,Positions!C:C,1,0)=C36) -> FALSE
A37: Healthcare | B37: Healthcare | C37: HCA | E37: 8.0729203 | F37: 19.863 | G37: 0.0076 | H37: 379.02 | I37: 22.53 | J37: 24.55 | K37: 0.0897 | L37: 1.7219497 | M37: 16.822903 | N37: 15.438697 | O37: 0.2853 | P37: =NOT(VLOOKUP(C37,Positions!C:C,1,0)=C37) -> FALSE
A38: Energy & Utilities | B38: Energy | C38: YPF | D38: 0.0449 | E38: 7.9344361 | F38: 22.017 | G38: 0 | H38: 34.35 | I38: 4.29 | J38: 4.7 | K38: 0.0956 | L38: 0.76471981 | M38: 8.006992 | N38: 7.308511 | O38: 0.4789 | P38: =NOT(VLOOKUP(C38,Positions!C:C,1,0)=C38) -> FALSE
A39: Consumer Def & Cyclical | B39: Consumer Cyclical | C39: APTV | E39: 7.9340021 | F39: 15.812 | G39: 0 | H39: 68.45 | I39: 6.12 | J39: 6.98 | K39: 0.1405 | L39: 0.69786431 | M39: 11.18464 | N39: 9.80659 | O39: 0.4027 | P39: =NOT(VLOOKUP(C39,Positions!C:C,1,0)=C39) -> FALSE
A40: Consumer Def & Cyclical | B40: Consumer Cyclical | C40: LEVI | E40: 5.6327028 | F40: 14.336 | G40: 0.0289 | H40: 18.62 | I40: 0.9 | J40: 1.4 | K40: 0.5556 | L40: 0.23940002 | M40: 20.68889 | N40: 13.300001 | O40: 0.4396 | P40: =NOT(VLOOKUP(C40,Positions!C:C,1,0)=C40) -> FALSE
...

Sheet PVT
A1: Ticker2 | B1: (All) | L1: WK50 | R1: WK05 Start | V1: WK05 | AC1: WK05 | AJ1: WK06 | AQ1: WK07 | AY1: WK08 | BG1: Weekly Return % | BH1: Annual % | BJ1: WK09 | BR1: Wkly | BS1: Annual | BU1: WK09 | CC1: Wkly | CD1: Annual | CF1: WK11 | CN1: Wkly | CO1: Annual | CQ1: WK12 | CY1: Wkly | CZ1: Annual | DB1: WK14 | DM1: WK18
L2: 46000 | R2: 45684 | V2: 45685 | AC2: 45688 | AJ2: 45695 | AQ2: 45702 | AY2: 45711 | BG2: =((AY14+BF14)/AY14)^(1/((AY2-AQ2)/7))-1 -> 0.007825058 | BH2: =(1+BG2)^(36)-1 -> 0.32393139 | BJ2: 45716 | BR2: =((BJ14+BQ14)/BJ14)^(1/((BJ2-AY2)/7))-1 -> -0.036296068 | BS2: =(1+BR2)^(36)-1 -> -0.73577694 | BU2: 45723 | CC2: =((BU14+CB14)/BU14)^(1/((BU2-BJ2)/7))-1 -> 0.001769385 | CD2: =(1+CC2)^(36)-1 -> 0.06571035 | CF2: 45730 | CN2: =((CF14+CM14)/CF14)^(1/((CF2-BU2)/7))-1 -> -0.024417601 | CO2: =(1+CN2)^(36)-1 -> -0.58932107 | CQ2: 45736 | CY2: =((CQ14+CX14)/CQ14)^(1/((CQ2-CF2)/7))-1 -> 0.016751469 | CZ2: =(1+CY2)^(36)-1 -> 0.8185829 | DB2: 45751 | DM2: 45778
